Workbook

Sheet Produksi
B2: PIT CONTROL | D2: Mine Ops Board / Produksi Plan vs Actual
B3: MINE OPS BOARD | D3: Produksi Plan vs Actual
D4: Overburden & coal getting dari ritase hauler · data dummy (simulasi) untuk portofolio
B5: BOARD
B6: =HYPERLINK("#Produksi!A1"," Produksi") | E6: Dari | F6: 46082 | H6: Sampai | I6: 46110 | K6: Shift | L6: Semua
B7: =HYPERLINK("#Digger!A1"," Produktivitas Digger") | D7: =IF(Kalkulasi!$B$9=0,"⚠ Tanggal akhir harus sama atau setelah tanggal mulai","Klik sel kuning untuk memilih filter · "&Kalkulasi!$B$9&" hari dipilih")
B8: =HYPERLINK("#Availability!A1"," Availability Unit")
B9: =HYPERLINK("#'Delay & Hujan'!A1"," Delay & Hujan") | D9: OB ACTUAL | G9: ACHIEVEMENT OB | J9: COAL ACTUAL | M9: ACHIEVEMENT COAL | P9: STRIPPING RATIO | S9: RITASE HAULER
B10: =HYPERLINK("#Fuel!A1"," Fuel") | D10: =Kalkulasi!$B$38 | G10: =Kalkulasi!$B$39 | J10: =Kalkulasi!$B$41 | M10: =Kalkulasi!$B$42 | P10: =Kalkulasi!$B$43 | S10: =Kalkulasi!$B$45+Kalkulasi!$B$46
B11: =HYPERLINK("#'Tren PTY'!A1"," Tren PTY") | D11: ="Plan "&TEXT(Kalkulasi!$B$37,"#,##0")&" BCM" | G11: =IF(Kalkulasi!$B$39>=1," ▲ Di atas plan"," Gap "&TEXT(Kalkulasi!$B$37-Kalkulasi!$B$38,"#,##0")&" BCM") | J11: ="Plan "&TEXT(Kalkulasi!$B$40,"#,##0")&" MT" | M11: =IF(Kalkulasi!$B$42>=1," ▲ Di atas plan"," Gap "&TEXT(Kalkulasi!$B$40-Kalkulasi!$B$41,"#,##0")&" MT") | P11: ="Plan "&TEXT(Kalkulasi!$B$44,"0.00")&" BCM/MT" | S11: ="OB "&TEXT(Kalkulasi!$B$45,"#,##0")&" · coal "&TEXT(Kalkulasi!$B$46,"#,##0")
B13: PER JAM | D13: Overburden: actual vs plan | O13: BCM · garis hijau = achievement kumulatif (%) | P13: Kontribusi OB per digger | U13: BCM
B14: =HYPERLINK("#'PTY per Jam'!A1"," PTY per Jam")
B15: =HYPERLINK("#'Fleet & Delay'!A1"," Fleet & Delay")
B16: =HYPERLINK("#'Daily Report'!A1"," Daily Report")
B17: =HYPERLINK("#INPUT_RITASE!A1"," Input ritase ↗")
B18: =HYPERLINK("#INPUT_DELAY!A1"," Input delay ↗")
B20: DATA
B21: =HYPERLINK("#'Master Data'!A1"," Master Data")
B22: =HYPERLINK("#DATA_TS!A1"," Tabel timesheet ↗")
B23: =HYPERLINK("#DATA_FUEL!A1"," Tabel fuel ↗")
P24: ="Total "&TEXT(SUM(Kalkulasi!$B$240:$B$245),"#,##0")&" BCM"
B25: LAINNYA | P25: ■ | Q25: =Kalkulasi!A240 | T25: =Kalkulasi!C240
B26: =HYPERLINK("#Panduan!A1"," Panduan") | P26: ■ | Q26: =Kalkulasi!A241 | T26: =Kalkulasi!C241
B27: =HYPERLINK("#Parameter!A1"," Target & parameter") | P27: ■ | Q27: =Kalkulasi!A242 | T27: =Kalkulasi!C242
B28: =HYPERLINK("#MASTER_JAM!A1"," Faktor, target & MF") | P28: ■ | Q28: =Kalkulasi!A243 | T28: =Kalkulasi!C243
P29: ■ | Q29: =Kalkulasi!A244 | T29: =Kalkulasi!C244
P30: ■ | Q30: =Kalkulasi!A245 | T30: =Kalkulasi!C245
B33: Data dummy · Coal Project | D33: Coal getting: actual vs plan | O33: MT | P33: Ringkasan periode
B34: Simulasi unit per shift,
B35: Maret 2026. Bukan data | P35: Hari dalam periode | S35: =Kalkulasi!$B$9
B36: perusahaan mana pun.
P37: Rata-rata OB / hari | S37: =IF(Kalkulasi!$B$9=0,0,Kalkulasi!$B$38/Kalkulasi!$B$9)
B38: Muhammad Rifqi Rizqullah
B39: Mine Operations Control | P39: Rata-rata coal / hari | S39: =IF(Kalkulasi!$B$9=0,0,Kalkulasi!$B$41/Kalkulasi!$B$9)
P41: Hari OB tertinggi | S41: =IFERROR(TEXT(INDEX(Kalkulasi!$B$81:$B$111,MATCH(MAX(Kalkulasi!$E$81:$E$111),Kalkulasi!$E$81:$E$111,0)),"d mmm")&" · "&TEXT(MAX(Kalkulasi!$E$81:$E$111),"#,##0"),"–")
P43: Hari OB ≥ plan | S43: =SUM(Kalkulasi!$I$81:$I$111)&" dari "&Kalkulasi!$B$9
P45: Porsi OB day shift | S45: =IF(Kalkulasi!$B$38=0,0,Kalkulasi!$B$47/Kalkulasi!$B$38)
P47: OB per ritase | S47: =IF(Kalkulasi!$B$45=0,0,Kalkulasi!$B$38/Kalkulasi!$B$45)

Sheet Digger
B2: PIT CONTROL | D2: Mine Ops Board / Produktivitas Digger
B3: MINE OPS BOARD | D3: Produktivitas Digger
D4: PTY excavator = produksi ÷ EWH · pilih digger untuk melihat tren hariannya
B5: BOARD
B6: =HYPERLINK("#Produksi!A1"," Produksi") | E6: Dari | F6: 46082 | H6: Sampai | I6: 46110 | K6: Shift | L6: Semua | N6: Digger | O6: Semua
B7: =HYPERLINK("#Digger!A1"," Produktivitas Digger") | D7: =IF(Kalkulasi!$B$16=0,"⚠ Tanggal akhir harus sama atau setelah tanggal mulai","Klik sel kuning untuk memilih filter · "&Kalkulasi!$B$16&" hari dipilih")
B8: =HYPERLINK("#Availability!A1"," Availability Unit")
B9: =HYPERLINK("#'Delay & Hujan'!A1"," Delay & Hujan") | D9: PTY OB FLEET | G9: PTY COAL | J9: DIGGER PTY TERTINGGI | M9: PRODUKSI OB DIGGER | P9: HM EXCAVATOR | S9: DIGGER AKTIF OB
B10: =HYPERLINK("#Fuel!A1"," Fuel") | D10: =Kalkulasi!$B$54 | G10: =Kalkulasi!$B$55 | J10: =IFERROR(INDEX($D$15:$D$32,MATCH(MAX($I$15:$I$32),$I$15:$I$32,0)),"–") | M10: =Kalkulasi!$B$50 | P10: =Kalkulasi!$B$56 | S10: =COUNTIF($H$15:$H$32,">0")
B11: =HYPERLINK("#'Tren PTY'!A1"," Tren PTY") | D11: ="EWH OB "&TEXT(Kalkulasi!$B$51,"#,##0")&" jam" | G11: ="EWH coal "&TEXT(Kalkulasi!$B$53,"#,##0")&" jam" | J11: =TEXT(MAX($I$15:$I$32),"#,##0")&" BCM/jam · "&IFERROR(INDEX($E$15:$E$32,MATCH(MAX($I$15:$I$32),$I$15:$I$32,0)),"") | M11: ="Semua excavator" | P11: ="EWH OB "&TEXT(IF(Kalkulasi!$B$56=0,0,Kalkulasi!$B$51/Kalkulasi!$B$56),"0%")&" dari HM" | S11: ="dari 18 excavator"
B13: PER JAM | D13: PTY per excavator | N13: baris biru = digger terpilih | O13: PTY OB (BCM/jam EWH) | U13: digger dengan produksi OB
B14: =HYPERLINK("#'PTY per Jam'!A1"," PTY per Jam") | D14: Unit | E14: Tipe | F14: HM | G14: EWH OB | H14: OB BCM | I14: PTY OB | J14: Ritase | K14: Coal MT | L14: PTY coal | M14: PA | N14: UA
B15: =HYPERLINK("#'Fleet & Delay'!A1"," Fleet & Delay") | D15: EX-1251 | E15: SY1250 | F15: =SUMIFS(DATA_TS!$G$2:$G$20001,DATA_TS!$A$2:$A$20001,">="&Kalkulasi!$B$12,DATA_TS!$A$2:$A$20001,"<="&Kalkulasi!$B$13,DATA_TS!$B$2:$B$20001,Kalkulasi!$B$14,DATA_TS!$C$2:$C$20001,$D15) | G15: =SUMIFS(DATA_TS!$M$2:$M$20001,DATA_TS!$A$2:$A$20001,">="&Kalkulasi!$B$12,DATA_TS!$A$2:$A$20001,"<="&Kalkulasi!$B$13,DATA_TS!$B$2:$B$20001,Kalkulasi!$B$14,DATA_TS!$C$2:$C$20001,$D15) | H15: =SUMIFS(DATA_TS!$Q$2:$Q$20001,DATA_TS!$A$2:$A$20001,">="&Kalkulasi!$B$12,DATA_TS!$A$2:$A$20001,"<="&Kalkulasi!$B$13,DATA_TS!$B$2:$B$20001,Kalkulasi!$B$14,DATA_TS!$C$2:$C$20001,$D15) | I15: =IF(G15=0,0,H15/G15) | J15: =SUMIFS(DATA_TS!$O$2:$O$20001,DATA_TS!$A$2:$A$20001,">="&Kalkulasi!$B$12,DATA_TS!$A$2:$A$20001,"<="&Kalkulasi!$B$13,DATA_TS!$B$2:$B$20001,Kalkulasi!$B$14,DATA_TS!$C$2:$C$20001,$D15) | K15: =SUMIFS(DATA_TS!$R$2:$R$20001,DATA_TS!$A$2:$A$20001,">="&Kalkulasi!$B$12,DATA_TS!$A$2:$A$20001,"<="&Kalkulasi!$B$13,DATA_TS!$B$2:$B$20001,Kalkulasi!$B$14,DATA_TS!$C$2:$C$20001,$D15) | L15: =IFERROR(K15/SUMIFS(DATA_TS!$N$2:$N$20001,DATA_TS!$A$2:$A$20001,">="&Kalkulasi!$B$12,DATA_TS!$A$2:$A$20001,"<="&Kalkulasi!$B$13,DATA_TS!$B$2:$B$20001,Kalkulasi!$B$14,DATA_TS!$C$2:$C$20001,$D15),0) | M15: =IF(F15+SUMIFS(DATA_TS!$J$2:$J$20001,DATA_TS!$A$2:$A$20001,">="&Kalkulasi!$B$12,DATA_TS!$A$2:$A$20001,"<="&Kalkulasi!$B$13,DATA_TS!$B$2:$B$20001,Kalkulasi!$B$14,DATA_TS!$C$2:$C$20001,$D15)+SUMIFS(DATA_TS!$K$2:$K$20001,DATA_TS!$A$2:$A$20001,">="&Kalkulasi!$B$12,DATA_TS!$A$2:$A$20001,"<="&Kalkulasi!$B$13,DATA_TS!$B$2:$B$20001,Kalkulasi!$B$14,DATA_TS!$C$2:$C$20001,$D15)=0,0,(F15+SUMIFS(DATA_TS!$K$2:$K$20001,DATA_TS!$A$2:$A$20001,">="&Kalkulasi!$B$12,DATA_TS!$A$2:$A$20001,"<="&Kalkulasi!$B$13,DATA_TS!$B$2:$B$20001,Kalkulasi!$B$14,DATA_TS!$C$2:$C$20001,$D15))/(F15+SUMIFS(DATA_TS!$J$2:$J$20001,DATA_TS!$A$2:$A$20001,">="&Kalkulasi!$B$12,DATA_TS!$A$2:$A$20001,"<="&Kalkulasi!$B$13,DATA_TS!$B$2:$B$20001,Kalkulasi!$B$14,DATA_TS!$C$2:$C$20001,$D15)+SUMIFS(DATA_TS!$K$2:$K$20001,DATA_TS!$A$2:$A$20001,">="&Kalkulasi!$B$12,DATA_TS!$A$2:$A$20001,"<="&Kalkulasi!$B$13,DATA_TS!$B$2:$B$20001,Kalkulasi!$B$14,DATA_TS!$C$2:$C$20001,$D15))) | N15: =IF(F15+SUMIFS(DATA_TS!$K$2:$K$20001,DATA_TS!$A$2:$A$20001,">="&Kalkulasi!$B$12,DATA_TS!$A$2:$A$20001,"<="&Kalkulasi!$B$13,DATA_TS!$B$2:$B$20001,Kalkulasi!$B$14,DATA_TS!$C$2:$C$20001,$D15)=0,0,F15/(F15+SUMIFS(DATA_TS!$K$2:$K$20001,DATA_TS!$A$2:$A$20001,">="&Kalkulasi!$B$12,DATA_TS!$A$2:$A$20001,"<="&Kalkulasi!$B$13,DATA_TS!$B$2:$B$20001,Kalkulasi!$B$14,DATA_TS!$C$2:$C$20001,$D15)))
B16: =HYPERLINK("#'Daily Report'!A1"," Daily Report") | D16: EX-755 | E16: SY750H-PRO | F16: =SUMIFS(DATA_TS!$G$2:$G$20001,DATA_TS!$A$2:$A$20001,">="&Kalkulasi!$B$12,DATA_TS!$A$2:$A$20001,"<="&Kalkulasi!$B$13,DATA_TS!$B$2:$B$20001,Kalkulasi!$B$14,DATA_TS!$C$2:$C$20001,$D16) | G16: =SUMIFS(DATA_TS!$M$2:$M$20001,DATA_TS!$A$2:$A$20001,">="&Kalkulasi!$B$12,DATA_TS!$A$2:$A$20001,"<="&Kalkulasi!$B$13,DATA_TS!$B$2:$B$20001,Kalkulasi!$B$14,DATA_TS!$C$2:$C$20001,$D16) | H16: =SUMIFS(DATA_TS!$Q$2:$Q$20001,DATA_TS!$A$2:$A$20001,">="&Kalkulasi!$B$12,DATA_TS!$A$2:$A$20001,"<="&Kalkulasi!$B$13,DATA_TS!$B$2:$B$20001,Kalkulasi!$B$14,DATA_TS!$C$2:$C$20001,$D16) | I16: =IF(G16=0,0,H16/G16) | J16: =SUMIFS(DATA_TS!$O$2:$O$20001,DATA_TS!$A$2:$A$20001,">="&Kalkulasi!$B$12,DATA_TS!$A$2:$A$20001,"<="&Kalkulasi!$B$13,DATA_TS!$B$2:$B$20001,Kalkulasi!$B$14,DATA_TS!$C$2:$C$20001,$D16) | K16: =SUMIFS(DATA_TS!$R$2:$R$20001,DATA_TS!$A$2:$A$20001,">="&Kalkulasi!$B$12,DATA_TS!$A$2:$A$20001,"<="&Kalkulasi!$B$13,DATA_TS!$B$2:$B$20001,Kalkulasi!$B$14,DATA_TS!$C$2:$C$20001,$D16) | L16: =IFERROR(K16/SUMIFS(DATA_TS!$N$2:$N$20001,DATA_TS!$A$2:$A$20001,">="&Kalkulasi!$B$12,DATA_TS!$A$2:$A$20001,"<="&Kalkulasi!$B$13,DATA_TS!$B$2:$B$20001,Kalkulasi!$B$14,DATA_TS!$C$2:$C$20001,$D16),0) | M16: =IF(F16+SUMIFS(DATA_TS!$J$2:$J$20001,DATA_TS!$A$2:$A$20001,">="&Kalkulasi!$B$12,DATA_TS!$A$2:$A$20001,"<="&Kalkulasi!$B$13,DATA_TS!$B$2:$B$20001,Kalkulasi!$B$14,DATA_TS!$C$2:$C$20001,$D16)+SUMIFS(DATA_TS!$K$2:$K$20001,DATA_TS!$A$2:$A$20001,">="&Kalkulasi!$B$12,DATA_TS!$A$2:$A$20001,"<="&Kalkulasi!$B$13,DATA_TS!$B$2:$B$20001,Kalkulasi!$B$14,DATA_TS!$C$2:$C$20001,$D16)=0,0,(F16+SUMIFS(DATA_TS!$K$2:$K$20001,DATA_TS!$A$2:$A$20001,">="&Kalkulasi!$B$12,DATA_TS!$A$2:$A$20001,"<="&Kalkulasi!$B$13,DATA_TS!$B$2:$B$20001,Kalkulasi!$B$14,DATA_TS!$C$2:$C$20001,$D16))/(F16+SUMIFS(DATA_TS!$J$2:$J$20001,DATA_TS!$A$2:$A$20001,">="&Kalkulasi!$B$12,DATA_TS!$A$2:$A$20001,"<="&Kalkulasi!$B$13,DATA_TS!$B$2:$B$20001,Kalkulasi!$B$14,DATA_TS!$C$2:$C$20001,$D16)+SUMIFS(DATA_TS!$K$2:$K$20001,DATA_TS!$A$2:$A$20001,">="&Kalkulasi!$B$12,DATA_TS!$A$2:$A$20001,"<="&Kalkulasi!$B$13,DATA_TS!$B$2:$B$20001,Kalkulasi!$B$14,DATA_TS!$C$2:$C$20001,$D16))) | N16: =IF(F16+SUMIFS(DATA_TS!$K$2:$K$20001,DATA_TS!$A$2:$A$20001,">="&Kalkulasi!$B$12,DATA_TS!$A$2:$A$20001,"<="&Kalkulasi!$B$13,DATA_TS!$B$2:$B$20001,Kalkulasi!$B$14,DATA_TS!$C$2:$C$20001,$D16)=0,0,F16/(F16+SUMIFS(DATA_TS!$K$2:$K$20001,DATA_TS!$A$2:$A$20001,">="&Kalkulasi!$B$12,DATA_TS!$A$2:$A$20001,"<="&Kalkulasi!$B$13,DATA_TS!$B$2:$B$20001,Kalkulasi!$B$14,DATA_TS!$C$2:$C$20001,$D16)))
B17: =HYPERLINK("#INPUT_RITASE!A1"," Input ritase ↗") | D17: EX-2101 | E17: SY2000 | F17: =SUMIFS(DATA_TS!$G$2:$G$20001,DATA_TS!$A$2:$A$20001,">="&Kalkulasi!$B$12,DATA_TS!$A$2:$A$20001,"<="&Kalkulasi!$B$13,DATA_TS!$B$2:$B$20001,Kalkulasi!$B$14,DATA_TS!$C$2:$C$20001,$D17) | G17: =SUMIFS(DATA_TS!$M$2:$M$20001,DATA_TS!$A$2:$A$20001,">="&Kalkulasi!$B$12,DATA_TS!$A$2:$A$20001,"<="&Kalkulasi!$B$13,DATA_TS!$B$2:$B$20001,Kalkulasi!$B$14,DATA_TS!$C$2:$C$20001,$D17) | H17: =SUMIFS(DATA_TS!$Q$2:$Q$20001,DATA_TS!$A$2:$A$20001,">="&Kalkulasi!$B$12,DATA_TS!$A$2:$A$20001,"<="&Kalkulasi!$B$13,DATA_TS!$B$2:$B$20001,Kalkulasi!$B$14,DATA_TS!$C$2:$C$20001,$D17) | I17: =IF(G17=0,0,H17/G17) | J17: =SUMIFS(DATA_TS!$O$2:$O$20001,DATA_TS!$A$2:$A$20001,">="&Kalkulasi!$B$12,DATA_TS!$A$2:$A$20001,"<="&Kalkulasi!$B$13,DATA_TS!$B$2:$B$20001,Kalkulasi!$B$14,DATA_TS!$C$2:$C$20001,$D17) | K17: =SUMIFS(DATA_TS!$R$2:$R$20001,DATA_TS!$A$2:$A$20001,">="&Kalkulasi!$B$12,DATA_TS!$A$2:$A$20001,"<="&Kalkulasi!$B$13,DATA_TS!$B$2:$B$20001,Kalkulasi!$B$14,DATA_TS!$C$2:$C$20001,$D17) | L17: =IFERROR(K17/SUMIFS(DATA_TS!$N$2:$N$20001,DATA_TS!$A$2:$A$20001,">="&Kalkulasi!$B$12,DATA_TS!$A$2:$A$20001,"<="&Kalkulasi!$B$13,DATA_TS!$B$2:$B$20001,Kalkulasi!$B$14,DATA_TS!$C$2:$C$20001,$D17),0) | M17: =IF(F17+SUMIFS(DATA_TS!$J$2:$J$20001,DATA_TS!$A$2:$A$20001,">="&Kalkulasi!$B$12,DATA_TS!$A$2:$A$20001,"<="&Kalkulasi!$B$13,DATA_TS!$B$2:$B$20001,Kalkulasi!$B$14,DATA_TS!$C$2:$C$20001,$D17)+SUMIFS(DATA_TS!$K$2:$K$20001,DATA_TS!$A$2:$A$20001,">="&Kalkulasi!$B$12,DATA_TS!$A$2:$A$20001,"<="&Kalkulasi!$B$13,DATA_TS!$B$2:$B$20001,Kalkulasi!$B$14,DATA_TS!$C$2:$C$20001,$D17)=0,0,(F17+SUMIFS(DATA_TS!$K$2:$K$20001,DATA_TS!$A$2:$A$20001,">="&Kalkulasi!$B$12,DATA_TS!$A$2:$A$20001,"<="&Kalkulasi!$B$13,DATA_TS!$B$2:$B$20001,Kalkulasi!$B$14,DATA_TS!$C$2:$C$20001,$D17))/(F17+SUMIFS(DATA_TS!$J$2:$J$20001,DATA_TS!$A$2:$A$20001,">="&Kalkulasi!$B$12,DATA_TS!$A$2:$A$20001,"<="&Kalkulasi!$B$13,DATA_TS!$B$2:$B$20001,Kalkulasi!$B$14,DATA_TS!$C$2:$C$20001,$D17)+SUMIFS(DATA_TS!$K$2:$K$20001,DATA_TS!$A$2:$A$20001,">="&Kalkulasi!$B$12,DATA_TS!$A$2:$A$20001,"<="&Kalkulasi!$B$13,DATA_TS!$B$2:$B$20001,Kalkulasi!$B$14,DATA_TS!$C$2:$C$20001,$D17))) | N17: =IF(F17+SUMIFS(DATA_TS!$K$2:$K$20001,DATA_TS!$A$2:$A$20001,">="&Kalkulasi!$B$12,DATA_TS!$A$2:$A$20001,"<="&Kalkulasi!$B$13,DATA_TS!$B$2:$B$20001,Kalkulasi!$B$14,DATA_TS!$C$2:$C$20001,$D17)=0,0,F17/(F17+SUMIFS(DATA_TS!$K$2:$K$20001,DATA_TS!$A$2:$A$20001,">="&Kalkulasi!$B$12,DATA_TS!$A$2:$A$20001,"<="&Kalkulasi!$B$13,DATA_TS!$B$2:$B$20001,Kalkulasi!$B$14,DATA_TS!$C$2:$C$20001,$D17)))
B18: =HYPERLINK("#INPUT_DELAY!A1"," Input delay ↗") | D18: EX-754 | E18: SY750H-PRO | F18: =SUMIFS(DATA_TS!$G$2:$G$20001,DATA_TS!$A$2:$A$20001,">="&Kalkulasi!$B$12,DATA_TS!$A$2:$A$20001,"<="&Kalkulasi!$B$13,DATA_TS!$B$2:$B$20001,Kalkulasi!$B$14,DATA_TS!$C$2:$C$20001,$D18) | G18: =SUMIFS(DATA_TS!$M$2:$M$20001,DATA_TS!$A$2:$A$20001,">="&Kalkulasi!$B$12,DATA_TS!$A$2:$A$20001,"<="&Kalkulasi!$B$13,DATA_TS!$B$2:$B$20001,Kalkulasi!$B$14,DATA_TS!$C$2:$C$20001,$D18) | H18: =SUMIFS(DATA_TS!$Q$2:$Q$20001,DATA_TS!$A$2:$A$20001,">="&Kalkulasi!$B$12,DATA_TS!$A$2:$A$20001,"<="&Kalkulasi!$B$13,DATA_TS!$B$2:$B$20001,Kalkulasi!$B$14,DATA_TS!$C$2:$C$20001,$D18) | I18: =IF(G18=0,0,H18/G18) | J18: =SUMIFS(DATA_TS!$O$2:$O$20001,DATA_TS!$A$2:$A$20001,">="&Kalkulasi!$B$12,DATA_TS!$A$2:$A$20001,"<="&Kalkulasi!$B$13,DATA_TS!$B$2:$B$20001,Kalkulasi!$B$14,DATA_TS!$C$2:$C$20001,$D18) | K18: =SUMIFS(DATA_TS!$R$2:$R$20001,DATA_TS!$A$2:$A$20001,">="&Kalkulasi!$B$12,DATA_TS!$A$2:$A$20001,"<="&Kalkulasi!$B$13,DATA_TS!$B$2:$B$20001,Kalkulasi!$B$14,DATA_TS!$C$2:$C$20001,$D18) | L18: =IFERROR(K18/SUMIFS(DATA_TS!$N$2:$N$20001,DATA_TS!$A$2:$A$20001,">="&Kalkulasi!$B$12,DATA_TS!$A$2:$A$20001,"<="&Kalkulasi!$B$13,DATA_TS!$B$2:$B$20001,Kalkulasi!$B$14,DATA_TS!$C$2:$C$20001,$D18),0) | M18: =IF(F18+SUMIFS(DATA_TS!$J$2:$J$20001,DATA_TS!$A$2:$A$20001,">="&Kalkulasi!$B$12,DATA_TS!$A$2:$A$20001,"<="&Kalkulasi!$B$13,DATA_TS!$B$2:$B$20001,Kalkulasi!$B$14,DATA_TS!$C$2:$C$20001,$D18)+SUMIFS(DATA_TS!$K$2:$K$20001,DATA_TS!$A$2:$A$20001,">="&Kalkulasi!$B$12,DATA_TS!$A$2:$A$20001,"<="&Kalkulasi!$B$13,DATA_TS!$B$2:$B$20001,Kalkulasi!$B$14,DATA_TS!$C$2:$C$20001,$D18)=0,0,(F18+SUMIFS(DATA_TS!$K$2:$K$20001,DATA_TS!$A$2:$A$20001,">="&Kalkulasi!$B$12,DATA_TS!$A$2:$A$20001,"<="&Kalkulasi!$B$13,DATA_TS!$B$2:$B$20001,Kalkulasi!$B$14,DATA_TS!$C$2:$C$20001,$D18))/(F18+SUMIFS(DATA_TS!$J$2:$J$20001,DATA_TS!$A$2:$A$20001,">="&Kalkulasi!$B$12,DATA_TS!$A$2:$A$20001,"<="&Kalkulasi!$B$13,DATA_TS!$B$2:$B$20001,Kalkulasi!$B$14,DATA_TS!$C$2:$C$20001,$D18)+SUMIFS(DATA_TS!$K$2:$K$20001,DATA_TS!$A$2:$A$20001,">="&Kalkulasi!$B$12,DATA_TS!$A$2:$A$20001,"<="&Kalkulasi!$B$13,DATA_TS!$B$2:$B$20001,Kalkulasi!$B$14,DATA_TS!$C$2:$C$20001,$D18))) | N18: =IF(F18+SUMIFS(DATA_TS!$K$2:$K$20001,DATA_TS!$A$2:$A$20001,">="&Kalkulasi!$B$12,DATA_TS!$A$2:$A$20001,"<="&Kalkulasi!$B$13,DATA_TS!$B$2:$B$20001,Kalkulasi!$B$14,DATA_TS!$C$2:$C$20001,$D18)=0,0,F18/(F18+SUMIFS(DATA_TS!$K$2:$K$20001,DATA_TS!$A$2:$A$20001,">="&Kalkulasi!$B$12,DATA_TS!$A$2:$A$20001,"<="&Kalkulasi!$B$13,DATA_TS!$B$2:$B$20001,Kalkulasi!$B$14,DATA_TS!$C$2:$C$20001,$D18)))
D19: EX-753 | E19: SY750H-PRO | F19: =SUMIFS(DATA_TS!$G$2:$G$20001,DATA_TS!$A$2:$A$20001,">="&Kalkulasi!$B$12,DATA_TS!$A$2:$A$20001,"<="&Kalkulasi!$B$13,DATA_TS!$B$2:$B$20001,Kalkulasi!$B$14,DATA_TS!$C$2:$C$20001,$D19) | G19: =SUMIFS(DATA_TS!$M$2:$M$20001,DATA_TS!$A$2:$A$20001,">="&Kalkulasi!$B$12,DATA_TS!$A$2:$A$20001,"<="&Kalkulasi!$B$13,DATA_TS!$B$2:$B$20001,Kalkulasi!$B$14,DATA_TS!$C$2:$C$20001,$D19) | H19: =SUMIFS(DATA_TS!$Q$2:$Q$20001,DATA_TS!$A$2:$A$20001,">="&Kalkulasi!$B$12,DATA_TS!$A$2:$A$20001,"<="&Kalkulasi!$B$13,DATA_TS!$B$2:$B$20001,Kalkulasi!$B$14,DATA_TS!$C$2:$C$20001,$D19) | I19: =IF(G19=0,0,H19/G19) | J19: =SUMIFS(DATA_TS!$O$2:$O$20001,DATA_TS!$A$2:$A$20001,">="&Kalkulasi!$B$12,DATA_TS!$A$2:$A$20001,"<="&Kalkulasi!$B$13,DATA_TS!$B$2:$B$20001,Kalkulasi!$B$14,DATA_TS!$C$2:$C$20001,$D19) | K19: =SUMIFS(DATA_TS!$R$2:$R$20001,DATA_TS!$A$2:$A$20001,">="&Kalkulasi!$B$12,DATA_TS!$A$2:$A$20001,"<="&Kalkulasi!$B$13,DATA_TS!$B$2:$B$20001,Kalkulasi!$B$14,DATA_TS!$C$2:$C$20001,$D19) | L19: =IFERROR(K19/SUMIFS(DATA_TS!$N$2:$N$20001,DATA_TS!$A$2:$A$20001,">="&Kalkulasi!$B$12,DATA_TS!$A$2:$A$20001,"<="&Kalkulasi!$B$13,DATA_TS!$B$2:$B$20001,Kalkulasi!$B$14,DATA_TS!$C$2:$C$20001,$D19),0) | M19: =IF(F19+SUMIFS(DATA_TS!$J$2:$J$20001,DATA_TS!$A$2:$A$20001,">="&Kalkulasi!$B$12,DATA_TS!$A$2:$A$20001,"<="&Kalkulasi!$B$13,DATA_TS!$B$2:$B$20001,Kalkulasi!$B$14,DATA_TS!$C$2:$C$20001,$D19)+SUMIFS(DATA_TS!$K$2:$K$20001,DATA_TS!$A$2:$A$20001,">="&Kalkulasi!$B$12,DATA_TS!$A$2:$A$20001,"<="&Kalkulasi!$B$13,DATA_TS!$B$2:$B$20001,Kalkulasi!$B$14,DATA_TS!$C$2:$C$20001,$D19)=0,0,(F19+SUMIFS(DATA_TS!$K$2:$K$20001,DATA_TS!$A$2:$A$20001,">="&Kalkulasi!$B$12,DATA_TS!$A$2:$A$20001,"<="&Kalkulasi!$B$13,DATA_TS!$B$2:$B$20001,Kalkulasi!$B$14,DATA_TS!$C$2:$C$20001,$D19))/(F19+SUMIFS(DATA_TS!$J$2:$J$20001,DATA_TS!$A$2:$A$20001,">="&Kalkulasi!$B$12,DATA_TS!$A$2:$A$20001,"<="&Kalkulasi!$B$13,DATA_TS!$B$2:$B$20001,Kalkulasi!$B$14,DATA_TS!$C$2:$C$20001,$D19)+SUMIFS(DATA_TS!$K$2:$K$20001,DATA_TS!$A$2:$A$20001,">="&Kalkulasi!$B$12,DATA_TS!$A$2:$A$20001,"<="&Kalkulasi!$B$13,DATA_TS!$B$2:$B$20001,Kalkulasi!$B$14,DATA_TS!$C$2:$C$20001,$D19))) | N19: =IF(F19+SUMIFS(DATA_TS!$K$2:$K$20001,DATA_TS!$A$2:$A$20001,">="&Kalkulasi!$B$12,DATA_TS!$A$2:$A$20001,"<="&Kalkulasi!$B$13,DATA_TS!$B$2:$B$20001,Kalkulasi!$B$14,DATA_TS!$C$2:$C$20001,$D19)=0,0,F19/(F19+SUMIFS(DATA_TS!$K$2:$K$20001,DATA_TS!$A$2:$A$20001,">="&Kalkulasi!$B$12,DATA_TS!$A$2:$A$20001,"<="&Kalkulasi!$B$13,DATA_TS!$B$2:$B$20001,Kalkulasi!$B$14,DATA_TS!$C$2:$C$20001,$D19)))
B20: DATA | D20: EX-1252 | E20: SY1250 | F20: =SUMIFS(DATA_TS!$G$2:$G$20001,DATA_TS!$A$2:$A$20001,">="&Kalkulasi!$B$12,DATA_TS!$A$2:$A$20001,"<="&Kalkulasi!$B$13,DATA_TS!$B$2:$B$20001,Kalkulasi!$B$14,DATA_TS!$C$2:$C$20001,$D20) | G20: =SUMIFS(DATA_TS!$M$2:$M$20001,DATA_TS!$A$2:$A$20001,">="&Kalkulasi!$B$12,DATA_TS!$A$2:$A$20001,"<="&Kalkulasi!$B$13,DATA_TS!$B$2:$B$20001,Kalkulasi!$B$14,DATA_TS!$C$2:$C$20001,$D20) | H20: =SUMIFS(DATA_TS!$Q$2:$Q$20001,DATA_TS!$A$2:$A$20001,">="&Kalkulasi!$B$12,DATA_TS!$A$2:$A$20001,"<="&Kalkulasi!$B$13,DATA_TS!$B$2:$B$20001,Kalkulasi!$B$14,DATA_TS!$C$2:$C$20001,$D20) | I20: =IF(G20=0,0,H20/G20) | J20: =SUMIFS(DATA_TS!$O$2:$O$20001,DATA_TS!$A$2:$A$20001,">="&Kalkulasi!$B$12,DATA_TS!$A$2:$A$20001,"<="&Kalkulasi!$B$13,DATA_TS!$B$2:$B$20001,Kalkulasi!$B$14,DATA_TS!$C$2:$C$20001,$D20) | K20: =SUMIFS(DATA_TS!$R$2:$R$20001,DATA_TS!$A$2:$A$20001,">="&Kalkulasi!$B$12,DATA_TS!$A$2:$A$20001,"<="&Kalkulasi!$B$13,DATA_TS!$B$2:$B$20001,Kalkulasi!$B$14,DATA_TS!$C$2:$C$20001,$D20) | L20: =IFERROR(K20/SUMIFS(DATA_TS!$N$2:$N$20001,DATA_TS!$A$2:$A$20001,">="&Kalkulasi!$B$12,DATA_TS!$A$2:$A$20001,"<="&Kalkulasi!$B$13,DATA_TS!$B$2:$B$20001,Kalkulasi!$B$14,DATA_TS!$C$2:$C$20001,$D20),0) | M20: =IF(F20+SUMIFS(DATA_TS!$J$2:$J$20001,DATA_TS!$A$2:$A$20001,">="&Kalkulasi!$B$12,DATA_TS!$A$2:$A$20001,"<="&Kalkulasi!$B$13,DATA_TS!$B$2:$B$20001,Kalkulasi!$B$14,DATA_TS!$C$2:$C$20001,$D20)+SUMIFS(DATA_TS!$K$2:$K$20001,DATA_TS!$A$2:$A$20001,">="&Kalkulasi!$B$12,DATA_TS!$A$2:$A$20001,"<="&Kalkulasi!$B$13,DATA_TS!$B$2:$B$20001,Kalkulasi!$B$14,DATA_TS!$C$2:$C$20001,$D20)=0,0,(F20+SUMIFS(DATA_TS!$K$2:$K$20001,DATA_TS!$A$2:$A$20001,">="&Kalkulasi!$B$12,DATA_TS!$A$2:$A$20001,"<="&Kalkulasi!$B$13,DATA_TS!$B$2:$B$20001,Kalkulasi!$B$14,DATA_TS!$C$2:$C$20001,$D20))/(F20+SUMIFS(DATA_TS!$J$2:$J$20001,DATA_TS!$A$2:$A$20001,">="&Kalkulasi!$B$12,DATA_TS!$A$2:$A$20001,"<="&Kalkulasi!$B$13,DATA_TS!$B$2:$B$20001,Kalkulasi!$B$14,DATA_TS!$C$2:$C$20001,$D20)+SUMIFS(DATA_TS!$K$2:$K$20001,DATA_TS!$A$2:$A$20001,">="&Kalkulasi!$B$12,DATA_TS!$A$2:$A$20001,"<="&Kalkulasi!$B$13,DATA_TS!$B$2:$B$20001,Kalkulasi!$B$14,DATA_TS!$C$2:$C$20001,$D20))) | N20: =IF(F20+SUMIFS(DATA_TS!$K$2:$K$20001,DATA_TS!$A$2:$A$20001,">="&Kalkulasi!$B$12,DATA_TS!$A$2:$A$20001,"<="&Kalkulasi!$B$13,DATA_TS!$B$2:$B$20001,Kalkulasi!$B$14,DATA_TS!$C$2:$C$20001,$D20)=0,0,F20/(F20+SUMIFS(DATA_TS!$K$2:$K$20001,DATA_TS!$A$2:$A$20001,">="&Kalkulasi!$B$12,DATA_TS!$A$2:$A$20001,"<="&Kalkulasi!$B$13,DATA_TS!$B$2:$B$20001,Kalkulasi!$B$14,DATA_TS!$C$2:$C$20001,$D20)))
B21: =HYPERLINK("#'Master Data'!A1"," Master Data") | D21: EX-334 | E21: PC 300-8MO | F21: =SUMIFS(DATA_TS!$G$2:$G$20001,DATA_TS!$A$2:$A$20001,">="&Kalkulasi!$B$12,DATA_TS!$A$2:$A$20001,"<="&Kalkulasi!$B$13,DATA_TS!$B$2:$B$20001,Kalkulasi!$B$14,DATA_TS!$C$2:$C$20001,$D21) | G21: =SUMIFS(DATA_TS!$M$2:$M$20001,DATA_TS!$A$2:$A$20001,">="&Kalkulasi!$B$12,DATA_TS!$A$2:$A$20001,"<="&Kalkulasi!$B$13,DATA_TS!$B$2:$B$20001,Kalkulasi!$B$14,DATA_TS!$C$2:$C$20001,$D21) | H21: =SUMIFS(DATA_TS!$Q$2:$Q$20001,DATA_TS!$A$2:$A$20001,">="&Kalkulasi!$B$12,DATA_TS!$A$2:$A$20001,"<="&Kalkulasi!$B$13,DATA_TS!$B$2:$B$20001,Kalkulasi!$B$14,DATA_TS!$C$2:$C$20001,$D21) | I21: =IF(G21=0,0,H21/G21) | J21: =SUMIFS(DATA_TS!$O$2:$O$20001,DATA_TS!$A$2:$A$20001,">="&Kalkulasi!$B$12,DATA_TS!$A$2:$A$20001,"<="&Kalkulasi!$B$13,DATA_TS!$B$2:$B$20001,Kalkulasi!$B$14,DATA_TS!$C$2:$C$20001,$D21) | K21: =SUMIFS(DATA_TS!$R$2:$R$20001,DATA_TS!$A$2:$A$20001,">="&Kalkulasi!$B$12,DATA_TS!$A$2:$A$20001,"<="&Kalkulasi!$B$13,DATA_TS!$B$2:$B$20001,Kalkulasi!$B$14,DATA_TS!$C$2:$C$20001,$D21) | L21: =IFERROR(K21/SUMIFS(DATA_TS!$N$2:$N$20001,DATA_TS!$A$2:$A$20001,">="&Kalkulasi!$B$12,DATA_TS!$A$2:$A$20001,"<="&Kalkulasi!$B$13,DATA_TS!$B$2:$B$20001,Kalkulasi!$B$14,DATA_TS!$C$2:$C$20001,$D21),0) | M21: =IF(F21+SUMIFS(DATA_TS!$J$2:$J$20001,DATA_TS!$A$2:$A$20001,">="&Kalkulasi!$B$12,DATA_TS!$A$2:$A$20001,"<="&Kalkulasi!$B$13,DATA_TS!$B$2:$B$20001,Kalkulasi!$B$14,DATA_TS!$C$2:$C$20001,$D21)+SUMIFS(DATA_TS!$K$2:$K$20001,DATA_TS!$A$2:$A$20001,">="&Kalkulasi!$B$12,DATA_TS!$A$2:$A$20001,"<="&Kalkulasi!$B$13,DATA_TS!$B$2:$B$20001,Kalkulasi!$B$14,DATA_TS!$C$2:$C$20001,$D21)=0,0,(F21+SUMIFS(DATA_TS!$K$2:$K$20001,DATA_TS!$A$2:$A$20001,">="&Kalkulasi!$B$12,DATA_TS!$A$2:$A$20001,"<="&Kalkulasi!$B$13,DATA_TS!$B$2:$B$20001,Kalkulasi!$B$14,DATA_TS!$C$2:$C$20001,$D21))/(F21+SUMIFS(DATA_TS!$J$2:$J$20001,DATA_TS!$A$2:$A$20001,">="&Kalkulasi!$B$12,DATA_TS!$A$2:$A$20001,"<="&Kalkulasi!$B$13,DATA_TS!$B$2:$B$20001,Kalkulasi!$B$14,DATA_TS!$C$2:$C$20001,$D21)+SUMIFS(DATA_TS!$K$2:$K$20001,DATA_TS!$A$2:$A$20001,">="&Kalkulasi!$B$12,DATA_TS!$A$2:$A$20001,"<="&Kalkulasi!$B$13,DATA_TS!$B$2:$B$20001,Kalkulasi!$B$14,DATA_TS!$C$2:$C$20001,$D21))) | N21: =IF(F21+SUMIFS(DATA_TS!$K$2:$K$20001,DATA_TS!$A$2:$A$20001,">="&Kalkulasi!$B$12,DATA_TS!$A$2:$A$20001,"<="&Kalkulasi!$B$13,DATA_TS!$B$2:$B$20001,Kalkulasi!$B$14,DATA_TS!$C$2:$C$20001,$D21)=0,0,F21/(F21+SUMIFS(DATA_TS!$K$2:$K$20001,DATA_TS!$A$2:$A$20001,">="&Kalkulasi!$B$12,DATA_TS!$A$2:$A$20001,"<="&Kalkulasi!$B$13,DATA_TS!$B$2:$B$20001,Kalkulasi!$B$14,DATA_TS!$C$2:$C$20001,$D21)))
B22: =HYPERLINK("#DATA_TS!A1"," Tabel timesheet ↗") | D22: EX-336 | E22: PC 300-8MO | F22: =SUMIFS(DATA_TS!$G$2:$G$20001,DATA_TS!$A$2:$A$20001,">="&Kalkulasi!$B$12,DATA_TS!$A$2:$A$20001,"<="&Kalkulasi!$B$13,DATA_TS!$B$2:$B$20001,Kalkulasi!$B$14,DATA_TS!$C$2:$C$20001,$D22) | G22: =SUMIFS(DATA_TS!$M$2:$M$20001,DATA_TS!$A$2:$A$20001,">="&Kalkulasi!$B$12,DATA_TS!$A$2:$A$20001,"<="&Kalkulasi!$B$13,DATA_TS!$B$2:$B$20001,Kalkulasi!$B$14,DATA_TS!$C$2:$C$20001,$D22) | H22: =SUMIFS(DATA_TS!$Q$2:$Q$20001,DATA_TS!$A$2:$A$20001,">="&Kalkulasi!$B$12,DATA_TS!$A$2:$A$20001,"<="&Kalkulasi!$B$13,DATA_TS!$B$2:$B$20001,Kalkulasi!$B$14,DATA_TS!$C$2:$C$20001,$D22) | I22: =IF(G22=0,0,H22/G22) | J22: =SUMIFS(DATA_TS!$O$2:$O$20001,DATA_TS!$A$2:$A$20001,">="&Kalkulasi!$B$12,DATA_TS!$A$2:$A$20001,"<="&Kalkulasi!$B$13,DATA_TS!$B$2:$B$20001,Kalkulasi!$B$14,DATA_TS!$C$2:$C$20001,$D22) | K22: =SUMIFS(DATA_TS!$R$2:$R$20001,DATA_TS!$A$2:$A$20001,">="&Kalkulasi!$B$12,DATA_TS!$A$2:$A$20001,"<="&Kalkulasi!$B$13,DATA_TS!$B$2:$B$20001,Kalkulasi!$B$14,DATA_TS!$C$2:$C$20001,$D22) | L22: =IFERROR(K22/SUMIFS(DATA_TS!$N$2:$N$20001,DATA_TS!$A$2:$A$20001,">="&Kalkulasi!$B$12,DATA_TS!$A$2:$A$20001,"<="&Kalkulasi!$B$13,DATA_TS!$B$2:$B$20001,Kalkulasi!$B$14,DATA_TS!$C$2:$C$20001,$D22),0) | M22: =IF(F22+SUMIFS(DATA_TS!$J$2:$J$20001,DATA_TS!$A$2:$A$20001,">="&Kalkulasi!$B$12,DATA_TS!$A$2:$A$20001,"<="&Kalkulasi!$B$13,DATA_TS!$B$2:$B$20001,Kalkulasi!$B$14,DATA_TS!$C$2:$C$20001,$D22)+SUMIFS(DATA_TS!$K$2:$K$20001,DATA_TS!$A$2:$A$20001,">="&Kalkulasi!$B$12,DATA_TS!$A$2:$A$20001,"<="&Kalkulasi!$B$13,DATA_TS!$B$2:$B$20001,Kalkulasi!$B$14,DATA_TS!$C$2:$C$20001,$D22)=0,0,(F22+SUMIFS(DATA_TS!$K$2:$K$20001,DATA_TS!$A$2:$A$20001,">="&Kalkulasi!$B$12,DATA_TS!$A$2:$A$20001,"<="&Kalkulasi!$B$13,DATA_TS!$B$2:$B$20001,Kalkulasi!$B$14,DATA_TS!$C$2:$C$20001,$D22))/(F22+SUMIFS(DATA_TS!$J$2:$J$20001,DATA_TS!$A$2:$A$20001,">="&Kalkulasi!$B$12,DATA_TS!$A$2:$A$20001,"<="&Kalkulasi!$B$13,DATA_TS!$B$2:$B$20001,Kalkulasi!$B$14,DATA_TS!$C$2:$C$20001,$D22)+SUMIFS(DATA_TS!$K$2:$K$20001,DATA_TS!$A$2:$A$20001,">="&Kalkulasi!$B$12,DATA_TS!$A$2:$A$20001,"<="&Kalkulasi!$B$13,DATA_TS!$B$2:$B$20001,Kalkulasi!$B$14,DATA_TS!$C$2:$C$20001,$D22))) | N22: =IF(F22+SUMIFS(DATA_TS!$K$2:$K$20001,DATA_TS!$A$2:$A$20001,">="&Kalkulasi!$B$12,DATA_TS!$A$2:$A$20001,"<="&Kalkulasi!$B$13,DATA_TS!$B$2:$B$20001,Kalkulasi!$B$14,DATA_TS!$C$2:$C$20001,$D22)=0,0,F22/(F22+SUMIFS(DATA_TS!$K$2:$K$20001,DATA_TS!$A$2:$A$20001,">="&Kalkulasi!$B$12,DATA_TS!$A$2:$A$20001,"<="&Kalkulasi!$B$13,DATA_TS!$B$2:$B$20001,Kalkulasi!$B$14,DATA_TS!$C$2:$C$20001,$D22)))
B23: =HYPERLINK("#DATA_FUEL!A1"," Tabel fuel ↗") | D23: EX-333 | E23: PC 300-8MO | F23: =SUMIFS(DATA_TS!$G$2:$G$20001,DATA_TS!$A$2:$A$20001,">="&Kalkulasi!$B$12,DATA_TS!$A$2:$A$20001,"<="&Kalkulasi!$B$13,DATA_TS!$B$2:$B$20001,Kalkulasi!$B$14,DATA_TS!$C$2:$C$20001,$D23) | G23: =SUMIFS(DATA_TS!$M$2:$M$20001,DATA_TS!$A$2:$A$20001,">="&Kalkulasi!$B$12,DATA_TS!$A$2:$A$20001,"<="&Kalkulasi!$B$13,DATA_TS!$B$2:$B$20001,Kalkulasi!$B$14,DATA_TS!$C$2:$C$20001,$D23) | H23: =SUMIFS(DATA_TS!$Q$2:$Q$20001,DATA_TS!$A$2:$A$20001,">="&Kalkulasi!$B$12,DATA_TS!$A$2:$A$20001,"<="&Kalkulasi!$B$13,DATA_TS!$B$2:$B$20001,Kalkulasi!$B$14,DATA_TS!$C$2:$C$20001,$D23) | I23: =IF(G23=0,0,H23/G23) | J23: =SUMIFS(DATA_TS!$O$2:$O$20001,DATA_TS!$A$2:$A$20001,">="&Kalkulasi!$B$12,DATA_TS!$A$2:$A$20001,"<="&Kalkulasi!$B$13,DATA_TS!$B$2:$B$20001,Kalkulasi!$B$14,DATA_TS!$C$2:$C$20001,$D23) | K23: =SUMIFS(DATA_TS!$R$2:$R$20001,DATA_TS!$A$2:$A$20001,">="&Kalkulasi!$B$12,DATA_TS!$A$2:$A$20001,"<="&Kalkulasi!$B$13,DATA_TS!$B$2:$B$20001,Kalkulasi!$B$14,DATA_TS!$C$2:$C$20001,$D23) | L23: =IFERROR(K23/SUMIFS(DATA_TS!$N$2:$N$20001,DATA_TS!$A$2:$A$20001,">="&Kalkulasi!$B$12,DATA_TS!$A$2:$A$20001,"<="&Kalkulasi!$B$13,DATA_TS!$B$2:$B$20001,Kalkulasi!$B$14,DATA_TS!$C$2:$C$20001,$D23),0) | M23: =IF(F23+SUMIFS(DATA_TS!$J$2:$J$20001,DATA_TS!$A$2:$A$20001,">="&Kalkulasi!$B$12,DATA_TS!$A$2:$A$20001,"<="&Kalkulasi!$B$13,DATA_TS!$B$2:$B$20001,Kalkulasi!$B$14,DATA_TS!$C$2:$C$20001,$D23)+SUMIFS(DATA_TS!$K$2:$K$20001,DATA_TS!$A$2:$A$20001,">="&Kalkulasi!$B$12,DATA_TS!$A$2:$A$20001,"<="&Kalkulasi!$B$13,DATA_TS!$B$2:$B$20001,Kalkulasi!$B$14,DATA_TS!$C$2:$C$20001,$D23)=0,0,(F23+SUMIFS(DATA_TS!$K$2:$K$20001,DATA_TS!$A$2:$A$20001,">="&Kalkulasi!$B$12,DATA_TS!$A$2:$A$20001,"<="&Kalkulasi!$B$13,DATA_TS!$B$2:$B$20001,Kalkulasi!$B$14,DATA_TS!$C$2:$C$20001,$D23))/(F23+SUMIFS(DATA_TS!$J$2:$J$20001,DATA_TS!$A$2:$A$20001,">="&Kalkulasi!$B$12,DATA_TS!$A$2:$A$20001,"<="&Kalkulasi!$B$13,DATA_TS!$B$2:$B$20001,Kalkulasi!$B$14,DATA_TS!$C$2:$C$20001,$D23)+SUMIFS(DATA_TS!$K$2:$K$20001,DATA_TS!$A$2:$A$20001,">="&Kalkulasi!$B$12,DATA_TS!$A$2:$A$20001,"<="&Kalkulasi!$B$13,DATA_TS!$B$2:$B$20001,Kalkulasi!$B$14,DATA_TS!$C$2:$C$20001,$D23))) | N23: =IF(F23+SUMIFS(DATA_TS!$K$2:$K$20001,DATA_TS!$A$2:$A$20001,">="&Kalkulasi!$B$12,DATA_TS!$A$2:$A$20001,"<="&Kalkulasi!$B$13,DATA_TS!$B$2:$B$20001,Kalkulasi!$B$14,DATA_TS!$C$2:$C$20001,$D23)=0,0,F23/(F23+SUMIFS(DATA_TS!$K$2:$K$20001,DATA_TS!$A$2:$A$20001,">="&Kalkulasi!$B$12,DATA_TS!$A$2:$A$20001,"<="&Kalkulasi!$B$13,DATA_TS!$B$2:$B$20001,Kalkulasi!$B$14,DATA_TS!$C$2:$C$20001,$D23)))
D24: EX-335 | E24: PC 300-8MO | F24: =SUMIFS(DATA_TS!$G$2:$G$20001,DATA_TS!$A$2:$A$20001,">="&Kalkulasi!$B$12,DATA_TS!$A$2:$A$20001,"<="&Kalkulasi!$B$13,DATA_TS!$B$2:$B$20001,Kalkulasi!$B$14,DATA_TS!$C$2:$C$20001,$D24) | G24: =SUMIFS(DATA_TS!$M$2:$M$20001,DATA_TS!$A$2:$A$20001,">="&Kalkulasi!$B$12,DATA_TS!$A$2:$A$20001,"<="&Kalkulasi!$B$13,DATA_TS!$B$2:$B$20001,Kalkulasi!$B$14,DATA_TS!$C$2:$C$20001,$D24) | H24: =SUMIFS(DATA_TS!$Q$2:$Q$20001,DATA_TS!$A$2:$A$20001,">="&Kalkulasi!$B$12,DATA_TS!$A$2:$A$20001,"<="&Kalkulasi!$B$13,DATA_TS!$B$2:$B$20001,Kalkulasi!$B$14,DATA_TS!$C$2:$C$20001,$D24) | I24: =IF(G24=0,0,H24/G24) | J24: =SUMIFS(DATA_TS!$O$2:$O$20001,DATA_TS!$A$2:$A$20001,">="&Kalkulasi!$B$12,DATA_TS!$A$2:$A$20001,"<="&Kalkulasi!$B$13,DATA_TS!$B$2:$B$20001,Kalkulasi!$B$14,DATA_TS!$C$2:$C$20001,$D24) | K24: =SUMIFS(DATA_TS!$R$2:$R$20001,DATA_TS!$A$2:$A$20001,">="&Kalkulasi!$B$12,DATA_TS!$A$2:$A$20001,"<="&Kalkulasi!$B$13,DATA_TS!$B$2:$B$20001,Kalkulasi!$B$14,DATA_TS!$C$2:$C$20001,$D24) | L24: =IFERROR(K24/SUMIFS(DATA_TS!$N$2:$N$20001,DATA_TS!$A$2:$A$20001,">="&Kalkulasi!$B$12,DATA_TS!$A$2:$A$20001,"<="&Kalkulasi!$B$13,DATA_TS!$B$2:$B$20001,Kalkulasi!$B$14,DATA_TS!$C$2:$C$20001,$D24),0) | M24: =IF(F24+SUMIFS(DATA_TS!$J$2:$J$20001,DATA_TS!$A$2:$A$20001,">="&Kalkulasi!$B$12,DATA_TS!$A$2:$A$20001,"<="&Kalkulasi!$B$13,DATA_TS!$B$2:$B$20001,Kalkulasi!$B$14,DATA_TS!$C$2:$C$20001,$D24)+SUMIFS(DATA_TS!$K$2:$K$20001,DATA_TS!$A$2:$A$20001,">="&Kalkulasi!$B$12,DATA_TS!$A$2:$A$20001,"<="&Kalkulasi!$B$13,DATA_TS!$B$2:$B$20001,Kalkulasi!$B$14,DATA_TS!$C$2:$C$20001,$D24)=0,0,(F24+SUMIFS(DATA_TS!$K$2:$K$20001,DATA_TS!$A$2:$A$20001,">="&Kalkulasi!$B$12,DATA_TS!$A$2:$A$20001,"<="&Kalkulasi!$B$13,DATA_TS!$B$2:$B$20001,Kalkulasi!$B$14,DATA_TS!$C$2:$C$20001,$D24))/(F24+SUMIFS(DATA_TS!$J$2:$J$20001,DATA_TS!$A$2:$A$20001,">="&Kalkulasi!$B$12,DATA_TS!$A$2:$A$20001,"<="&Kalkulasi!$B$13,DATA_TS!$B$2:$B$20001,Kalkulasi!$B$14,DATA_TS!$C$2:$C$20001,$D24)+SUMIFS(DATA_TS!$K$2:$K$20001,DATA_TS!$A$2:$A$20001,">="&Kalkulasi!$B$12,DATA_TS!$A$2:$A$20001,"<="&Kalkulasi!$B$13,DATA_TS!$B$2:$B$20001,Kalkulasi!$B$14,DATA_TS!$C$2:$C$20001,$D24))) | N24: =IF(F24+SUMIFS(DATA_TS!$K$2:$K$20001,DATA_TS!$A$2:$A$20001,">="&Kalkulasi!$B$12,DATA_TS!$A$2:$A$20001,"<="&Kalkulasi!$B$13,DATA_TS!$B$2:$B$20001,Kalkulasi!$B$14,DATA_TS!$C$2:$C$20001,$D24)=0,0,F24/(F24+SUMIFS(DATA_TS!$K$2:$K$20001,DATA_TS!$A$2:$A$20001,">="&Kalkulasi!$B$12,DATA_TS!$A$2:$A$20001,"<="&Kalkulasi!$B$13,DATA_TS!$B$2:$B$20001,Kalkulasi!$B$14,DATA_TS!$C$2:$C$20001,$D24)))
B25: LAINNYA | D25: EX-332 | E25: PC 300-8MO | F25: =SUMIFS(DATA_TS!$G$2:$G$20001,DATA_TS!$A$2:$A$20001,">="&Kalkulasi!$B$12,DATA_TS!$A$2:$A$20001,"<="&Kalkulasi!$B$13,DATA_TS!$B$2:$B$20001,Kalkulasi!$B$14,DATA_TS!$C$2:$C$20001,$D25) | G25: =SUMIFS(DATA_TS!$M$2:$M$20001,DATA_TS!$A$2:$A$20001,">="&Kalkulasi!$B$12,DATA_TS!$A$2:$A$20001,"<="&Kalkulasi!$B$13,DATA_TS!$B$2:$B$20001,Kalkulasi!$B$14,DATA_TS!$C$2:$C$20001,$D25) | H25: =SUMIFS(DATA_TS!$Q$2:$Q$20001,DATA_TS!$A$2:$A$20001,">="&Kalkulasi!$B$12,DATA_TS!$A$2:$A$20001,"<="&Kalkulasi!$B$13,DATA_TS!$B$2:$B$20001,Kalkulasi!$B$14,DATA_TS!$C$2:$C$20001,$D25) | I25: =IF(G25=0,0,H25/G25) | J25: =SUMIFS(DATA_TS!$O$2:$O$20001,DATA_TS!$A$2:$A$20001,">="&Kalkulasi!$B$12,DATA_TS!$A$2:$A$20001,"<="&Kalkulasi!$B$13,DATA_TS!$B$2:$B$20001,Kalkulasi!$B$14,DATA_TS!$C$2:$C$20001,$D25) | K25: =SUMIFS(DATA_TS!$R$2:$R$20001,DATA_TS!$A$2:$A$20001,">="&Kalkulasi!$B$12,DATA_TS!$A$2:$A$20001,"<="&Kalkulasi!$B$13,DATA_TS!$B$2:$B$20001,Kalkulasi!$B$14,DATA_TS!$C$2:$C$20001,$D25) | L25: =IFERROR(K25/SUMIFS(DATA_TS!$N$2:$N$20001,DATA_TS!$A$2:$A$20001,">="&Kalkulasi!$B$12,DATA_TS!$A$2:$A$20001,"<="&Kalkulasi!$B$13,DATA_TS!$B$2:$B$20001,Kalkulasi!$B$14,DATA_TS!$C$2:$C$20001,$D25),0) | M25: =IF(F25+SUMIFS(DATA_TS!$J$2:$J$20001,DATA_TS!$A$2:$A$20001,">="&Kalkulasi!$B$12,DATA_TS!$A$2:$A$20001,"<="&Kalkulasi!$B$13,DATA_TS!$B$2:$B$20001,Kalkulasi!$B$14,DATA_TS!$C$2:$C$20001,$D25)+SUMIFS(DATA_TS!$K$2:$K$20001,DATA_TS!$A$2:$A$20001,">="&Kalkulasi!$B$12,DATA_TS!$A$2:$A$20001,"<="&Kalkulasi!$B$13,DATA_TS!$B$2:$B$20001,Kalkulasi!$B$14,DATA_TS!$C$2:$C$20001,$D25)=0,0,(F25+SUMIFS(DATA_TS!$K$2:$K$20001,DATA_TS!$A$2:$A$20001,">="&Kalkulasi!$B$12,DATA_TS!$A$2:$A$20001,"<="&Kalkulasi!$B$13,DATA_TS!$B$2:$B$20001,Kalkulasi!$B$14,DATA_TS!$C$2:$C$20001,$D25))/(F25+SUMIFS(DATA_TS!$J$2:$J$20001,DATA_TS!$A$2:$A$20001,">="&Kalkulasi!$B$12,DATA_TS!$A$2:$A$20001,"<="&Kalkulasi!$B$13,DATA_TS!$B$2:$B$20001,Kalkulasi!$B$14,DATA_TS!$C$2:$C$20001,$D25)+SUMIFS(DATA_TS!$K$2:$K$20001,DATA_TS!$A$2:$A$20001,">="&Kalkulasi!$B$12,DATA_TS!$A$2:$A$20001,"<="&Kalkulasi!$B$13,DATA_TS!$B$2:$B$20001,Kalkulasi!$B$14,DATA_TS!$C$2:$C$20001,$D25))) | N25: =IF(F25+SUMIFS(DATA_TS!$K$2:$K$20001,DATA_TS!$A$2:$A$20001,">="&Kalkulasi!$B$12,DATA_TS!$A$2:$A$20001,"<="&Kalkulasi!$B$13,DATA_TS!$B$2:$B$20001,Kalkulasi!$B$14,DATA_TS!$C$2:$C$20001,$D25)=0,0,F25/(F25+SUMIFS(DATA_TS!$K$2:$K$20001,DATA_TS!$A$2:$A$20001,">="&Kalkulasi!$B$12,DATA_TS!$A$2:$A$20001,"<="&Kalkulasi!$B$13,DATA_TS!$B$2:$B$20001,Kalkulasi!$B$14,DATA_TS!$C$2:$C$20001,$D25)))
B26: =HYPERLINK("#Panduan!A1"," Panduan") | D26: EX-222 | E26: PC 200-8MI | F26: =SUMIFS(DATA_TS!$G$2:$G$20001,DATA_TS!$A$2:$A$20001,">="&Kalkulasi!$B$12,DATA_TS!$A$2:$A$20001,"<="&Kalkulasi!$B$13,DATA_TS!$B$2:$B$20001,Kalkulasi!$B$14,DATA_TS!$C$2:$C$20001,$D26) | G26: =SUMIFS(DATA_TS!$M$2:$M$20001,DATA_TS!$A$2:$A$20001,">="&Kalkulasi!$B$12,DATA_TS!$A$2:$A$20001,"<="&Kalkulasi!$B$13,DATA_TS!$B$2:$B$20001,Kalkulasi!$B$14,DATA_TS!$C$2:$C$20001,$D26) | H26: =SUMIFS(DATA_TS!$Q$2:$Q$20001,DATA_TS!$A$2:$A$20001,">="&Kalkulasi!$B$12,DATA_TS!$A$2:$A$20001,"<="&Kalkulasi!$B$13,DATA_TS!$B$2:$B$20001,Kalkulasi!$B$14,DATA_TS!$C$2:$C$20001,$D26) | I26: =IF(G26=0,0,H26/G26) | J26: =SUMIFS(DATA_TS!$O$2:$O$20001,DATA_TS!$A$2:$A$20001,">="&Kalkulasi!$B$12,DATA_TS!$A$2:$A$20001,"<="&Kalkulasi!$B$13,DATA_TS!$B$2:$B$20001,Kalkulasi!$B$14,DATA_TS!$C$2:$C$20001,$D26) | K26: =SUMIFS(DATA_TS!$R$2:$R$20001,DATA_TS!$A$2:$A$20001,">="&Kalkulasi!$B$12,DATA_TS!$A$2:$A$20001,"<="&Kalkulasi!$B$13,DATA_TS!$B$2:$B$20001,Kalkulasi!$B$14,DATA_TS!$C$2:$C$20001,$D26) | L26: =IFERROR(K26/SUMIFS(DATA_TS!$N$2:$N$20001,DATA_TS!$A$2:$A$20001,">="&Kalkulasi!$B$12,DATA_TS!$A$2:$A$20001,"<="&Kalkulasi!$B$13,DATA_TS!$B$2:$B$20001,Kalkulasi!$B$14,DATA_TS!$C$2:$C$20001,$D26),0) | M26: =IF(F26+SUMIFS(DATA_TS!$J$2:$J$20001,DATA_TS!$A$2:$A$20001,">="&Kalkulasi!$B$12,DATA_TS!$A$2:$A$20001,"<="&Kalkulasi!$B$13,DATA_TS!$B$2:$B$20001,Kalkulasi!$B$14,DATA_TS!$C$2:$C$20001,$D26)+SUMIFS(DATA_TS!$K$2:$K$20001,DATA_TS!$A$2:$A$20001,">="&Kalkulasi!$B$12,DATA_TS!$A$2:$A$20001,"<="&Kalkulasi!$B$13,DATA_TS!$B$2:$B$20001,Kalkulasi!$B$14,DATA_TS!$C$2:$C$20001,$D26)=0,0,(F26+SUMIFS(DATA_TS!$K$2:$K$20001,DATA_TS!$A$2:$A$20001,">="&Kalkulasi!$B$12,DATA_TS!$A$2:$A$20001,"<="&Kalkulasi!$B$13,DATA_TS!$B$2:$B$20001,Kalkulasi!$B$14,DATA_TS!$C$2:$C$20001,$D26))/(F26+SUMIFS(DATA_TS!$J$2:$J$20001,DATA_TS!$A$2:$A$20001,">="&Kalkulasi!$B$12,DATA_TS!$A$2:$A$20001,"<="&Kalkulasi!$B$13,DATA_TS!$B$2:$B$20001,Kalkulasi!$B$14,DATA_TS!$C$2:$C$20001,$D26)+SUMIFS(DATA_TS!$K$2:$K$20001,DATA_TS!$A$2:$A$20001,">="&Kalkulasi!$B$12,DATA_TS!$A$2:$A$20001,"<="&Kalkulasi!$B$13,DATA_TS!$B$2:$B$20001,Kalkulasi!$B$14,DATA_TS!$C$2:$C$20001,$D26))) | N26: =IF(F26+SUMIFS(DATA_TS!$K$2:$K$20001,DATA_TS!$A$2:$A$20001,">="&Kalkulasi!$B$12,DATA_TS!$A$2:$A$20001,"<="&Kalkulasi!$B$13,DATA_TS!$B$2:$B$20001,Kalkulasi!$B$14,DATA_TS!$C$2:$C$20001,$D26)=0,0,F26/(F26+SUMIFS(DATA_TS!$K$2:$K$20001,DATA_TS!$A$2:$A$20001,">="&Kalkulasi!$B$12,DATA_TS!$A$2:$A$20001,"<="&Kalkulasi!$B$13,DATA_TS!$B$2:$B$20001,Kalkulasi!$B$14,DATA_TS!$C$2:$C$20001,$D26)))
B27: =HYPERLINK("#Parameter!A1"," Target & parameter") | D27: EX-223 | E27: PC 200-8MI | F27: =SUMIFS(DATA_TS!$G$2:$G$20001,DATA_TS!$A$2:$A$20001,">="&Kalkulasi!$B$12,DATA_TS!$A$2:$A$20001,"<="&Kalkulasi!$B$13,DATA_TS!$B$2:$B$20001,Kalkulasi!$B$14,DATA_TS!$C$2:$C$20001,$D27) | G27: =SUMIFS(DATA_TS!$M$2:$M$20001,DATA_TS!$A$2:$A$20001,">="&Kalkulasi!$B$12,DATA_TS!$A$2:$A$20001,"<="&Kalkulasi!$B$13,DATA_TS!$B$2:$B$20001,Kalkulasi!$B$14,DATA_TS!$C$2:$C$20001,$D27) | H27: =SUMIFS(DATA_TS!$Q$2:$Q$20001,DATA_TS!$A$2:$A$20001,">="&Kalkulasi!$B$12,DATA_TS!$A$2:$A$20001,"<="&Kalkulasi!$B$13,DATA_TS!$B$2:$B$20001,Kalkulasi!$B$14,DATA_TS!$C$2:$C$20001,$D27) | I27: =IF(G27=0,0,H27/G27) | J27: =SUMIFS(DATA_TS!$O$2:$O$20001,DATA_TS!$A$2:$A$20001,">="&Kalkulasi!$B$12,DATA_TS!$A$2:$A$20001,"<="&Kalkulasi!$B$13,DATA_TS!$B$2:$B$20001,Kalkulasi!$B$14,DATA_TS!$C$2:$C$20001,$D27) | K27: =SUMIFS(DATA_TS!$R$2:$R$20001,DATA_TS!$A$2:$A$20001,">="&Kalkulasi!$B$12,DATA_TS!$A$2:$A$20001,"<="&Kalkulasi!$B$13,DATA_TS!$B$2:$B$20001,Kalkulasi!$B$14,DATA_TS!$C$2:$C$20001,$D27) | L27: =IFERROR(K27/SUMIFS(DATA_TS!$N$2:$N$20001,DATA_TS!$A$2:$A$20001,">="&Kalkulasi!$B$12,DATA_TS!$A$2:$A$20001,"<="&Kalkulasi!$B$13,DATA_TS!$B$2:$B$20001,Kalkulasi!$B$14,DATA_TS!$C$2:$C$20001,$D27),0) | M27: =IF(F27+SUMIFS(DATA_TS!$J$2:$J$20001,DATA_TS!$A$2:$A$20001,">="&Kalkulasi!$B$12,DATA_TS!$A$2:$A$20001,"<="&Kalkulasi!$B$13,DATA_TS!$B$2:$B$20001,Kalkulasi!$B$14,DATA_TS!$C$2:$C$20001,$D27)+SUMIFS(DATA_TS!$K$2:$K$20001,DATA_TS!$A$2:$A$20001,">="&Kalkulasi!$B$12,DATA_TS!$A$2:$A$20001,"<="&Kalkulasi!$B$13,DATA_TS!$B$2:$B$20001,Kalkulasi!$B$14,DATA_TS!$C$2:$C$20001,$D27)=0,0,(F27+SUMIFS(DATA_TS!$K$2:$K$20001,DATA_TS!$A$2:$A$20001,">="&Kalkulasi!$B$12,DATA_TS!$A$2:$A$20001,"<="&Kalkulasi!$B$13,DATA_TS!$B$2:$B$20001,Kalkulasi!$B$14,DATA_TS!$C$2:$C$20001,$D27))/(F27+SUMIFS(DATA_TS!$J$2:$J$20001,DATA_TS!$A$2:$A$20001,">="&Kalkulasi!$B$12,DATA_TS!$A$2:$A$20001,"<="&Kalkulasi!$B$13,DATA_TS!$B$2:$B$20001,Kalkulasi!$B$14,DATA_TS!$C$2:$C$20001,$D27)+SUMIFS(DATA_TS!$K$2:$K$20001,DATA_TS!$A$2:$A$20001,">="&Kalkulasi!$B$12,DATA_TS!$A$2:$A$20001,"<="&Kalkulasi!$B$13,DATA_TS!$B$2:$B$20001,Kalkulasi!$B$14,DATA_TS!$C$2:$C$20001,$D27))) | N27: =IF(F27+SUMIFS(DATA_TS!$K$2:$K$20001,DATA_TS!$A$2:$A$20001,">="&Kalkulasi!$B$12,DATA_TS!$A$2:$A$20001,"<="&Kalkulasi!$B$13,DATA_TS!$B$2:$B$20001,Kalkulasi!$B$14,DATA_TS!$C$2:$C$20001,$D27)=0,0,F27/(F27+SUMIFS(DATA_TS!$K$2:$K$20001,DATA_TS!$A$2:$A$20001,">="&Kalkulasi!$B$12,DATA_TS!$A$2:$A$20001,"<="&Kalkulasi!$B$13,DATA_TS!$B$2:$B$20001,Kalkulasi!$B$14,DATA_TS!$C$2:$C$20001,$D27)))
B28: =HYPERLINK("#MASTER_JAM!A1"," Faktor, target & MF") | D28: EX-221 | E28: PC 200-8MI | F28: =SUMIFS(DATA_TS!$G$2:$G$20001,DATA_TS!$A$2:$A$20001,">="&Kalkulasi!$B$12,DATA_TS!$A$2:$A$20001,"<="&Kalkulasi!$B$13,DATA_TS!$B$2:$B$20001,Kalkulasi!$B$14,DATA_TS!$C$2:$C$20001,$D28) | G28: =SUMIFS(DATA_TS!$M$2:$M$20001,DATA_TS!$A$2:$A$20001,">="&Kalkulasi!$B$12,DATA_TS!$A$2:$A$20001,"<="&Kalkulasi!$B$13,DATA_TS!$B$2:$B$20001,Kalkulasi!$B$14,DATA_TS!$C$2:$C$20001,$D28) | H28: =SUMIFS(DATA_TS!$Q$2:$Q$20001,DATA_TS!$A$2:$A$20001,">="&Kalkulasi!$B$12,DATA_TS!$A$2:$A$20001,"<="&Kalkulasi!$B$13,DATA_TS!$B$2:$B$20001,Kalkulasi!$B$14,DATA_TS!$C$2:$C$20001,$D28) | I28: =IF(G28=0,0,H28/G28) | J28: =SUMIFS(DATA_TS!$O$2:$O$20001,DATA_TS!$A$2:$A$20001,">="&Kalkulasi!$B$12,DATA_TS!$A$2:$A$20001,"<="&Kalkulasi!$B$13,DATA_TS!$B$2:$B$20001,Kalkulasi!$B$14,DATA_TS!$C$2:$C$20001,$D28) | K28: =SUMIFS(DATA_TS!$R$2:$R$20001,DATA_TS!$A$2:$A$20001,">="&Kalkulasi!$B$12,DATA_TS!$A$2:$A$20001,"<="&Kalkulasi!$B$13,DATA_TS!$B$2:$B$20001,Kalkulasi!$B$14,DATA_TS!$C$2:$C$20001,$D28) | L28: =IFERROR(K28/SUMIFS(DATA_TS!$N$2:$N$20001,DATA_TS!$A$2:$A$20001,">="&Kalkulasi!$B$12,DATA_TS!$A$2:$A$20001,"<="&Kalkulasi!$B$13,DATA_TS!$B$2:$B$20001,Kalkulasi!$B$14,DATA_TS!$C$2:$C$20001,$D28),0) | M28: =IF(F28+SUMIFS(DATA_TS!$J$2:$J$20001,DATA_TS!$A$2:$A$20001,">="&Kalkulasi!$B$12,DATA_TS!$A$2:$A$20001,"<="&Kalkulasi!$B$13,DATA_TS!$B$2:$B$20001,Kalkulasi!$B$14,DATA_TS!$C$2:$C$20001,$D28)+SUMIFS(DATA_TS!$K$2:$K$20001,DATA_TS!$A$2:$A$20001,">="&Kalkulasi!$B$12,DATA_TS!$A$2:$A$20001,"<="&Kalkulasi!$B$13,DATA_TS!$B$2:$B$20001,Kalkulasi!$B$14,DATA_TS!$C$2:$C$20001,$D28)=0,0,(F28+SUMIFS(DATA_TS!$K$2:$K$20001,DATA_TS!$A$2:$A$20001,">="&Kalkulasi!$B$12,DATA_TS!$A$2:$A$20001,"<="&Kalkulasi!$B$13,DATA_TS!$B$2:$B$20001,Kalkulasi!$B$14,DATA_TS!$C$2:$C$20001,$D28))/(F28+SUMIFS(DATA_TS!$J$2:$J$20001,DATA_TS!$A$2:$A$20001,">="&Kalkulasi!$B$12,DATA_TS!$A$2:$A$20001,"<="&Kalkulasi!$B$13,DATA_TS!$B$2:$B$20001,Kalkulasi!$B$14,DATA_TS!$C$2:$C$20001,$D28)+SUMIFS(DATA_TS!$K$2:$K$20001,DATA_TS!$A$2:$A$20001,">="&Kalkulasi!$B$12,DATA_TS!$A$2:$A$20001,"<="&Kalkulasi!$B$13,DATA_TS!$B$2:$B$20001,Kalkulasi!$B$14,DATA_TS!$C$2:$C$20001,$D28))) | N28: =IF(F28+SUMIFS(DATA_TS!$K$2:$K$20001,DATA_TS!$A$2:$A$20001,">="&Kalkulasi!$B$12,DATA_TS!$A$2:$A$20001,"<="&Kalkulasi!$B$13,DATA_TS!$B$2:$B$20001,Kalkulasi!$B$14,DATA_TS!$C$2:$C$20001,$D28)=0,0,F28/(F28+SUMIFS(DATA_TS!$K$2:$K$20001,DATA_TS!$A$2:$A$20001,">="&Kalkulasi!$B$12,DATA_TS!$A$2:$A$20001,"<="&Kalkulasi!$B$13,DATA_TS!$B$2:$B$20001,Kalkulasi!$B$14,DATA_TS!$C$2:$C$20001,$D28)))
D29: EX-225 | E29: PC 200-8 | F29: =SUMIFS(DATA_TS!$G$2:$G$20001,DATA_TS!$A$2:$A$20001,">="&Kalkulasi!$B$12,DATA_TS!$A$2:$A$20001,"<="&Kalkulasi!$B$13,DATA_TS!$B$2:$B$20001,Kalkulasi!$B$14,DATA_TS!$C$2:$C$20001,$D29) | G29: =SUMIFS(DATA_TS!$M$2:$M$20001,DATA_TS!$A$2:$A$20001,">="&Kalkulasi!$B$12,DATA_TS!$A$2:$A$20001,"<="&Kalkulasi!$B$13,DATA_TS!$B$2:$B$20001,Kalkulasi!$B$14,DATA_TS!$C$2:$C$20001,$D29) | H29: =SUMIFS(DATA_TS!$Q$2:$Q$20001,DATA_TS!$A$2:$A$20001,">="&Kalkulasi!$B$12,DATA_TS!$A$2:$A$20001,"<="&Kalkulasi!$B$13,DATA_TS!$B$2:$B$20001,Kalkulasi!$B$14,DATA_TS!$C$2:$C$20001,$D29) | I29: =IF(G29=0,0,H29/G29) | J29: =SUMIFS(DATA_TS!$O$2:$O$20001,DATA_TS!$A$2:$A$20001,">="&Kalkulasi!$B$12,DATA_TS!$A$2:$A$20001,"<="&Kalkulasi!$B$13,DATA_TS!$B$2:$B$20001,Kalkulasi!$B$14,DATA_TS!$C$2:$C$20001,$D29) | K29: =SUMIFS(DATA_TS!$R$2:$R$20001,DATA_TS!$A$2:$A$20001,">="&Kalkulasi!$B$12,DATA_TS!$A$2:$A$20001,"<="&Kalkulasi!$B$13,DATA_TS!$B$2:$B$20001,Kalkulasi!$B$14,DATA_TS!$C$2:$C$20001,$D29) | L29: =IFERROR(K29/SUMIFS(DATA_TS!$N$2:$N$20001,DATA_TS!$A$2:$A$20001,">="&Kalkulasi!$B$12,DATA_TS!$A$2:$A$20001,"<="&Kalkulasi!$B$13,DATA_TS!$B$2:$B$20001,Kalkulasi!$B$14,DATA_TS!$C$2:$C$20001,$D29),0) | M29: =IF(F29+SUMIFS(DATA_TS!$J$2:$J$20001,DATA_TS!$A$2:$A$20001,">="&Kalkulasi!$B$12,DATA_TS!$A$2:$A$20001,"<="&Kalkulasi!$B$13,DATA_TS!$B$2:$B$20001,Kalkulasi!$B$14,DATA_TS!$C$2:$C$20001,$D29)+SUMIFS(DATA_TS!$K$2:$K$20001,DATA_TS!$A$2:$A$20001,">="&Kalkulasi!$B$12,DATA_TS!$A$2:$A$20001,"<="&Kalkulasi!$B$13,DATA_TS!$B$2:$B$20001,Kalkulasi!$B$14,DATA_TS!$C$2:$C$20001,$D29)=0,0,(F29+SUMIFS(DATA_TS!$K$2:$K$20001,DATA_TS!$A$2:$A$20001,">="&Kalkulasi!$B$12,DATA_TS!$A$2:$A$20001,"<="&Kalkulasi!$B$13,DATA_TS!$B$2:$B$20001,Kalkulasi!$B$14,DATA_TS!$C$2:$C$20001,$D29))/(F29+SUMIFS(DATA_TS!$J$2:$J$20001,DATA_TS!$A$2:$A$20001,">="&Kalkulasi!$B$12,DATA_TS!$A$2:$A$20001,"<="&Kalkulasi!$B$13,DATA_TS!$B$2:$B$20001,Kalkulasi!$B$14,DATA_TS!$C$2:$C$20001,$D29)+SUMIFS(DATA_TS!$K$2:$K$20001,DATA_TS!$A$2:$A$20001,">="&Kalkulasi!$B$12,DATA_TS!$A$2:$A$20001,"<="&Kalkulasi!$B$13,DATA_TS!$B$2:$B$20001,Kalkulasi!$B$14,DATA_TS!$C$2:$C$20001,$D29))) | N29: =IF(F29+SUMIFS(DATA_TS!$K$2:$K$20001,DATA_TS!$A$2:$A$20001,">="&Kalkulasi!$B$12,DATA_TS!$A$2:$A$20001,"<="&Kalkulasi!$B$13,DATA_TS!$B$2:$B$20001,Kalkulasi!$B$14,DATA_TS!$C$2:$C$20001,$D29)=0,0,F29/(F29+SUMIFS(DATA_TS!$K$2:$K$20001,DATA_TS!$A$2:$A$20001,">="&Kalkulasi!$B$12,DATA_TS!$A$2:$A$20001,"<="&Kalkulasi!$B$13,DATA_TS!$B$2:$B$20001,Kalkulasi!$B$14,DATA_TS!$C$2:$C$20001,$D29)))
D30: EX-331 | E30: PC 300-8MO | F30: =SUMIFS(DATA_TS!$G$2:$G$20001,DATA_TS!$A$2:$A$20001,">="&Kalkulasi!$B$12,DATA_TS!$A$2:$A$20001,"<="&Kalkulasi!$B$13,DATA_TS!$B$2:$B$20001,Kalkulasi!$B$14,DATA_TS!$C$2:$C$20001,$D30) | G30: =SUMIFS(DATA_TS!$M$2:$M$20001,DATA_TS!$A$2:$A$20001,">="&Kalkulasi!$B$12,DATA_TS!$A$2:$A$20001,"<="&Kalkulasi!$B$13,DATA_TS!$B$2:$B$20001,Kalkulasi!$B$14,DATA_TS!$C$2:$C$20001,$D30) | H30: =SUMIFS(DATA_TS!$Q$2:$Q$20001,DATA_TS!$A$2:$A$20001,">="&Kalkulasi!$B$12,DATA_TS!$A$2:$A$20001,"<="&Kalkulasi!$B$13,DATA_TS!$B$2:$B$20001,Kalkulasi!$B$14,DATA_TS!$C$2:$C$20001,$D30) | I30: =IF(G30=0,0,H30/G30) | J30: =SUMIFS(DATA_TS!$O$2:$O$20001,DATA_TS!$A$2:$A$20001,">="&Kalkulasi!$B$12,DATA_TS!$A$2:$A$20001,"<="&Kalkulasi!$B$13,DATA_TS!$B$2:$B$20001,Kalkulasi!$B$14,DATA_TS!$C$2:$C$20001,$D30) | K30: =SUMIFS(DATA_TS!$R$2:$R$20001,DATA_TS!$A$2:$A$20001,">="&Kalkulasi!$B$12,DATA_TS!$A$2:$A$20001,"<="&Kalkulasi!$B$13,DATA_TS!$B$2:$B$20001,Kalkulasi!$B$14,DATA_TS!$C$2:$C$20001,$D30) | L30: =IFERROR(K30/SUMIFS(DATA_TS!$N$2:$N$20001,DATA_TS!$A$2:$A$20001,">="&Kalkulasi!$B$12,DATA_TS!$A$2:$A$20001,"<="&Kalkulasi!$B$13,DATA_TS!$B$2:$B$20001,Kalkulasi!$B$14,DATA_TS!$C$2:$C$20001,$D30),0) | M30: =IF(F30+SUMIFS(DATA_TS!$J$2:$J$20001,DATA_TS!$A$2:$A$20001,">="&Kalkulasi!$B$12,DATA_TS!$A$2:$A$20001,"<="&Kalkulasi!$B$13,DATA_TS!$B$2:$B$20001,Kalkulasi!$B$14,DATA_TS!$C$2:$C$20001,$D30)+SUMIFS(DATA_TS!$K$2:$K$20001,DATA_TS!$A$2:$A$20001,">="&Kalkulasi!$B$12,DATA_TS!$A$2:$A$20001,"<="&Kalkulasi!$B$13,DATA_TS!$B$2:$B$20001,Kalkulasi!$B$14,DATA_TS!$C$2:$C$20001,$D30)=0,0,(F30+SUMIFS(DATA_TS!$K$2:$K$20001,DATA_TS!$A$2:$A$20001,">="&Kalkulasi!$B$12,DATA_TS!$A$2:$A$20001,"<="&Kalkulasi!$B$13,DATA_TS!$B$2:$B$20001,Kalkulasi!$B$14,DATA_TS!$C$2:$C$20001,$D30))/(F30+SUMIFS(DATA_TS!$J$2:$J$20001,DATA_TS!$A$2:$A$20001,">="&Kalkulasi!$B$12,DATA_TS!$A$2:$A$20001,"<="&Kalkulasi!$B$13,DATA_TS!$B$2:$B$20001,Kalkulasi!$B$14,DATA_TS!$C$2:$C$20001,$D30)+SUMIFS(DATA_TS!$K$2:$K$20001,DATA_TS!$A$2:$A$20001,">="&Kalkulasi!$B$12,DATA_TS!$A$2:$A$20001,"<="&Kalkulasi!$B$13,DATA_TS!$B$2:$B$20001,Kalkulasi!$B$14,DATA_TS!$C$2:$C$20001,$D30))) | N30: =IF(F30+SUMIFS(DATA_TS!$K$2:$K$20001,DATA_TS!$A$2:$A$20001,">="&Kalkulasi!$B$12,DATA_TS!$A$2:$A$20001,"<="&Kalkulasi!$B$13,DATA_TS!$B$2:$B$20001,Kalkulasi!$B$14,DATA_TS!$C$2:$C$20001,$D30)=0,0,F30/(F30+SUMIFS(DATA_TS!$K$2:$K$20001,DATA_TS!$A$2:$A$20001,">="&Kalkulasi!$B$12,DATA_TS!$A$2:$A$20001,"<="&Kalkulasi!$B$13,DATA_TS!$B$2:$B$20001,Kalkulasi!$B$14,DATA_TS!$C$2:$C$20001,$D30)))
D31: EX-751 | E31: SY750H-PRO | F31: =SUMIFS(DATA_TS!$G$2:$G$20001,DATA_TS!$A$2:$A$20001,">="&Kalkulasi!$B$12,DATA_TS!$A$2:$A$20001,"<="&Kalkulasi!$B$13,DATA_TS!$B$2:$B$20001,Kalkulasi!$B$14,DATA_TS!$C$2:$C$20001,$D31) | G31: =SUMIFS(DATA_TS!$M$2:$M$20001,DATA_TS!$A$2:$A$20001,">="&Kalkulasi!$B$12,DATA_TS!$A$2:$A$20001,"<="&Kalkulasi!$B$13,DATA_TS!$B$2:$B$20001,Kalkulasi!$B$14,DATA_TS!$C$2:$C$20001,$D31) | H31: =SUMIFS(DATA_TS!$Q$2:$Q$20001,DATA_TS!$A$2:$A$20001,">="&Kalkulasi!$B$12,DATA_TS!$A$2:$A$20001,"<="&Kalkulasi!$B$13,DATA_TS!$B$2:$B$20001,Kalkulasi!$B$14,DATA_TS!$C$2:$C$20001,$D31) | I31: =IF(G31=0,0,H31/G31) | J31: =SUMIFS(DATA_TS!$O$2:$O$20001,DATA_TS!$A$2:$A$20001,">="&Kalkulasi!$B$12,DATA_TS!$A$2:$A$20001,"<="&Kalkulasi!$B$13,DATA_TS!$B$2:$B$20001,Kalkulasi!$B$14,DATA_TS!$C$2:$C$20001,$D31) | K31: =SUMIFS(DATA_TS!$R$2:$R$20001,DATA_TS!$A$2:$A$20001,">="&Kalkulasi!$B$12,DATA_TS!$A$2:$A$20001,"<="&Kalkulasi!$B$13,DATA_TS!$B$2:$B$20001,Kalkulasi!$B$14,DATA_TS!$C$2:$C$20001,$D31) | L31: =IFERROR(K31/SUMIFS(DATA_TS!$N$2:$N$20001,DATA_TS!$A$2:$A$20001,">="&Kalkulasi!$B$12,DATA_TS!$A$2:$A$20001,"<="&Kalkulasi!$B$13,DATA_TS!$B$2:$B$20001,Kalkulasi!$B$14,DATA_TS!$C$2:$C$20001,$D31),0) | M31: =IF(F31+SUMIFS(DATA_TS!$J$2:$J$20001,DATA_TS!$A$2:$A$20001,">="&Kalkulasi!$B$12,DATA_TS!$A$2:$A$20001,"<="&Kalkulasi!$B$13,DATA_TS!$B$2:$B$20001,Kalkulasi!$B$14,DATA_TS!$C$2:$C$20001,$D31)+SUMIFS(DATA_TS!$K$2:$K$20001,DATA_TS!$A$2:$A$20001,">="&Kalkulasi!$B$12,DATA_TS!$A$2:$A$20001,"<="&Kalkulasi!$B$13,DATA_TS!$B$2:$B$20001,Kalkulasi!$B$14,DATA_TS!$C$2:$C$20001,$D31)=0,0,(F31+SUMIFS(DATA_TS!$K$2:$K$20001,DATA_TS!$A$2:$A$20001,">="&Kalkulasi!$B$12,DATA_TS!$A$2:$A$20001,"<="&Kalkulasi!$B$13,DATA_TS!$B$2:$B$20001,Kalkulasi!$B$14,DATA_TS!$C$2:$C$20001,$D31))/(F31+SUMIFS(DATA_TS!$J$2:$J$20001,DATA_TS!$A$2:$A$20001,">="&Kalkulasi!$B$12,DATA_TS!$A$2:$A$20001,"<="&Kalkulasi!$B$13,DATA_TS!$B$2:$B$20001,Kalkulasi!$B$14,DATA_TS!$C$2:$C$20001,$D31)+SUMIFS(DATA_TS!$K$2:$K$20001,DATA_TS!$A$2:$A$20001,">="&Kalkulasi!$B$12,DATA_TS!$A$2:$A$20001,"<="&Kalkulasi!$B$13,DATA_TS!$B$2:$B$20001,Kalkulasi!$B$14,DATA_TS!$C$2:$C$20001,$D31))) | N31: =IF(F31+SUMIFS(DATA_TS!$K$2:$K$20001,DATA_TS!$A$2:$A$20001,">="&Kalkulasi!$B$12,DATA_TS!$A$2:$A$20001,"<="&Kalkulasi!$B$13,DATA_TS!$B$2:$B$20001,Kalkulasi!$B$14,DATA_TS!$C$2:$C$20001,$D31)=0,0,F31/(F31+SUMIFS(DATA_TS!$K$2:$K$20001,DATA_TS!$A$2:$A$20001,">="&Kalkulasi!$B$12,DATA_TS!$A$2:$A$20001,"<="&Kalkulasi!$B$13,DATA_TS!$B$2:$B$20001,Kalkulasi!$B$14,DATA_TS!$C$2:$C$20001,$D31)))
D32: EX-752 | E32: SY750H-PRO | F32: =SUMIFS(DATA_TS!$G$2:$G$20001,DATA_TS!$A$2:$A$20001,">="&Kalkulasi!$B$12,DATA_TS!$A$2:$A$20001,"<="&Kalkulasi!$B$13,DATA_TS!$B$2:$B$20001,Kalkulasi!$B$14,DATA_TS!$C$2:$C$20001,$D32) | G32: =SUMIFS(DATA_TS!$M$2:$M$20001,DATA_TS!$A$2:$A$20001,">="&Kalkulasi!$B$12,DATA_TS!$A$2:$A$20001,"<="&Kalkulasi!$B$13,DATA_TS!$B$2:$B$20001,Kalkulasi!$B$14,DATA_TS!$C$2:$C$20001,$D32) | H32: =SUMIFS(DATA_TS!$Q$2:$Q$20001,DATA_TS!$A$2:$A$20001,">="&Kalkulasi!$B$12,DATA_TS!$A$2:$A$20001,"<="&Kalkulasi!$B$13,DATA_TS!$B$2:$B$20001,Kalkulasi!$B$14,DATA_TS!$C$2:$C$20001,$D32) | I32: =IF(G32=0,0,H32/G32) | J32: =SUMIFS(DATA_TS!$O$2:$O$20001,DATA_TS!$A$2:$A$20001,">="&Kalkulasi!$B$12,DATA_TS!$A$2:$A$20001,"<="&Kalkulasi!$B$13,DATA_TS!$B$2:$B$20001,Kalkulasi!$B$14,DATA_TS!$C$2:$C$20001,$D32) | K32: =SUMIFS(DATA_TS!$R$2:$R$20001,DATA_TS!$A$2:$A$20001,">="&Kalkulasi!$B$12,DATA_TS!$A$2:$A$20001,"<="&Kalkulasi!$B$13,DATA_TS!$B$2:$B$20001,Kalkulasi!$B$14,DATA_TS!$C$2:$C$20001,$D32) | L32: =IFERROR(K32/SUMIFS(DATA_TS!$N$2:$N$20001,DATA_TS!$A$2:$A$20001,">="&Kalkulasi!$B$12,DATA_TS!$A$2:$A$20001,"<="&Kalkulasi!$B$13,DATA_TS!$B$2:$B$20001,Kalkulasi!$B$14,DATA_TS!$C$2:$C$20001,$D32),0) | M32: =IF(F32+SUMIFS(DATA_TS!$J$2:$J$20001,DATA_TS!$A$2:$A$20001,">="&Kalkulasi!$B$12,DATA_TS!$A$2:$A$20001,"<="&Kalkulasi!$B$13,DATA_TS!$B$2:$B$20001,Kalkulasi!$B$14,DATA_TS!$C$2:$C$20001,$D32)+SUMIFS(DATA_TS!$K$2:$K$20001,DATA_TS!$A$2:$A$20001,">="&Kalkulasi!$B$12,DATA_TS!$A$2:$A$20001,"<="&Kalkulasi!$B$13,DATA_TS!$B$2:$B$20001,Kalkulasi!$B$14,DATA_TS!$C$2:$C$20001,$D32)=0,0,(F32+SUMIFS(DATA_TS!$K$2:$K$20001,DATA_TS!$A$2:$A$20001,">="&Kalkulasi!$B$12,DATA_TS!$A$2:$A$20001,"<="&Kalkulasi!$B$13,DATA_TS!$B$2:$B$20001,Kalkulasi!$B$14,DATA_TS!$C$2:$C$20001,$D32))/(F32+SUMIFS(DATA_TS!$J$2:$J$20001,DATA_TS!$A$2:$A$20001,">="&Kalkulasi!$B$12,DATA_TS!$A$2:$A$20001,"<="&Kalkulasi!$B$13,DATA_TS!$B$2:$B$20001,Kalkulasi!$B$14,DATA_TS!$C$2:$C$20001,$D32)+SUMIFS(DATA_TS!$K$2:$K$20001,DATA_TS!$A$2:$A$20001,">="&Kalkulasi!$B$12,DATA_TS!$A$2:$A$20001,"<="&Kalkulasi!$B$13,DATA_TS!$B$2:$B$20001,Kalkulasi!$B$14,DATA_TS!$C$2:$C$20001,$D32))) | N32: =IF(F32+SUMIFS(DATA_TS!$K$2:$K$20001,DATA_TS!$A$2:$A$20001,">="&Kalkulasi!$B$12,DATA_TS!$A$2:$A$20001,"<="&Kalkulasi!$B$13,DATA_TS!$B$2:$B$20001,Kalkulasi!$B$14,DATA_TS!$C$2:$C$20001,$D32)=0,0,F32/(F32+SUMIFS(DATA_TS!$K$2:$K$20001,DATA_TS!$A$2:$A$20001,">="&Kalkulasi!$B$12,DATA_TS!$A$2:$A$20001,"<="&Kalkulasi!$B$13,DATA_TS!$B$2:$B$20001,Kalkulasi!$B$14,DATA_TS!$C$2:$C$20001,$D32)))
B33: Data dummy · Coal Project
B34: Simulasi unit per shift,
B35: Maret 2026. Bukan data | D35: ="Tren harian "&IF($O$6="Semua","semua digger",$O$6) | U35: batang = produksi OB (BCM) · garis = PTY OB (BCM/jam)
B36: perusahaan mana pun.
B38: Muhammad Rifqi Rizqullah
B39: Mine Operations Control

Sheet Availability
B2: PIT CONTROL | D2: Mine Ops Board / Availability Unit
B3: MINE OPS BOARD | D3: Availability Unit
D4: PA = (HM+Idle)/(HM+Idle+BD) · UA = HM/(HM+Idle) · definisi timesheet site
B5: BOARD
B6: =HYPERLINK("#Produksi!A1"," Produksi") | E6: Dari | F6: 46082 | H6: Sampai | I6: 46110 | K6: Shift | L6: Semua | N6: Class | O6: Semua | Q6: Unit | R6: Semua
B7: =HYPERLINK("#Digger!A1"," Produktivitas Digger") | D7: =IF(Kalkulasi!$B$24=0,"⚠ Tanggal akhir harus sama atau setelah tanggal mulai","Klik sel kuning untuk memilih filter · "&Kalkulasi!$B$24&" hari dipilih")
B8: =HYPERLINK("#Availability!A1"," Availability Unit")
B9: =HYPERLINK("#'Delay & Hujan'!A1"," Delay & Hujan") | D9: PHYSICAL AVAILABILITY | G9: USE OF AVAILABILITY | J9: MECH. AVAILABILITY | M9: EFFECTIVE UTILIZATION | P9: WORKING HOURS | S9: BREAKDOWN
B10: =HYPERLINK("#Fuel!A1"," Fuel") | D10: =Kalkulasi!$B$63 | G10: =Kalkulasi!$B$64 | J10: =Kalkulasi!$B$65 | M10: =Kalkulasi!$B$66 | P10: =Kalkulasi!$B$59 | S10: =Kalkulasi!$B$60
B11: =HYPERLINK("#'Tren PTY'!A1"," Tren PTY") | D11: ="Target "&TEXT(Parameter!$C$5,"0%") | G11: ="Target "&TEXT(Parameter!$C$6,"0%") | J11: ="HM ÷ (HM + BD)" | M11: ="HM ÷ (HM + BD + Idle)" | P11: =TEXT(Kalkulasi!$B$67,"0")&" unit tercatat" | S11: =" "&TEXT(Kalkulasi!$B$68,"0%")&" tak terjadwal"
B13: PER JAM | D13: PA & UA per class | O13: % · mengikuti tanggal & shift | P13: Breakdown | U13: jam unit
B14: =HYPERLINK("#'PTY per Jam'!A1"," PTY per Jam")
B15: =HYPERLINK("#'Fleet & Delay'!A1"," Fleet & Delay")
B16: =HYPERLINK("#'Daily Report'!A1"," Daily Report")
B17: =HYPERLINK("#INPUT_RITASE!A1"," Input ritase ↗")
B18: =HYPERLINK("#INPUT_DELAY!A1"," Input delay ↗")
B20: DATA
B21: =HYPERLINK("#'Master Data'!A1"," Master Data")
B22: =HYPERLINK("#DATA_TS!A1"," Tabel timesheet ↗")
B23: =HYPERLINK("#DATA_FUEL!A1"," Tabel fuel ↗")
P24: ="Total "&TEXT(Kalkulasi!$B$60,"#,##0")&" jam BD"
B25: LAINNYA
B26: =HYPERLINK("#Panduan!A1"," Panduan") | P26: ■ | Q26: Tak terjadwal | T26: =Kalkulasi!$B$61
B27: =HYPERLINK("#Parameter!A1"," Target & parameter")
B28: =HYPERLINK("#MASTER_JAM!A1"," Faktor, target & MF") | P28: ■ | Q28: Terjadwal (servis) | T28: =Kalkulasi!$B$69
D32: Tren PA & UA harian | O32: % · unit sesuai filter · garis putus = target PA | P32: Top 10 unit breakdown | U32: jam BD
B33: Data dummy · Coal Project
B34: Simulasi unit per shift, | P34: # | Q34: Unit | R34: Class | T34: BD jam | U34: PA
B35: Maret 2026. Bukan data | P35: 1 | Q35: =IF(T35=0,"–",INDEX(LIST!$A$3:$A$112,MATCH(LARGE(LIST!$I$3:$I$112,1),LIST!$I$3:$I$112,0))) | R35: =IF(T35=0,"",INDEX(LIST!$C$3:$C$112,MATCH(LARGE(LIST!$I$3:$I$112,1),LIST!$I$3:$I$112,0))) | T35: =ROUND(INDEX(LIST!$E$3:$E$112,MATCH(LARGE(LIST!$I$3:$I$112,1),LIST!$I$3:$I$112,0)),1) | U35: =IF(T35=0,"",INDEX(LIST!$H$3:$H$112,MATCH(LARGE(LIST!$I$3:$I$112,1),LIST!$I$3:$I$112,0)))
B36: perusahaan mana pun. | P36: 2 | Q36: =IF(T36=0,"–",INDEX(LIST!$A$3:$A$112,MATCH(LARGE(LIST!$I$3:$I$112,2),LIST!$I$3:$I$112,0))) | R36: =IF(T36=0,"",INDEX(LIST!$C$3:$C$112,MATCH(LARGE(LIST!$I$3:$I$112,2),LIST!$I$3:$I$112,0))) | T36: =ROUND(INDEX(LIST!$E$3:$E$112,MATCH(LARGE(LIST!$I$3:$I$112,2),LIST!$I$3:$I$112,0)),1) | U36: =IF(T36=0,"",INDEX(LIST!$H$3:$H$112,MATCH(LARGE(LIST!$I$3:$I$112,2),LIST!$I$3:$I$112,0)))
P37: 3 | Q37: =IF(T37=0,"–",INDEX(LIST!$A$3:$A$112,MATCH(LARGE(LIST!$I$3:$I$112,3),LIST!$I$3:$I$112,0))) | R37: =IF(T37=0,"",INDEX(LIST!$C$3:$C$112,MATCH(LARGE(LIST!$I$3:$I$112,3),LIST!$I$3:$I$112,0))) | T37: =ROUND(INDEX(LIST!$E$3:$E$112,MATCH(LARGE(LIST!$I$3:$I$112,3),LIST!$I$3:$I$112,0)),1) | U37: =IF(T37=0,"",INDEX(LIST!$H$3:$H$112,MATCH(LARGE(LIST!$I$3:$I$112,3),LIST!$I$3:$I$112,0)))
B38: Muhammad Rifqi Rizqullah | P38: 4 | Q38: =IF(T38=0,"–",INDEX(LIST!$A$3:$A$112,MATCH(LARGE(LIST!$I$3:$I$112,4),LIST!$I$3:$I$112,0))) | R38: =IF(T38=0,"",INDEX(LIST!$C$3:$C$112,MATCH(LARGE(LIST!$I$3:$I$112,4),LIST!$I$3:$I$112,0))) | T38: =ROUND(INDEX(LIST!$E$3:$E$112,MATCH(LARGE(LIST!$I$3:$I$112,4),LIST!$I$3:$I$112,0)),1) | U38: =IF(T38=0,"",INDEX(LIST!$H$3:$H$112,MATCH(LARGE(LIST!$I$3:$I$112,4),LIST!$I$3:$I$112,0)))
B39: Mine Operations Control | P39: 5 | Q39: =IF(T39=0,"–",INDEX(LIST!$A$3:$A$112,MATCH(LARGE(LIST!$I$3:$I$112,5),LIST!$I$3:$I$112,0))) | R39: =IF(T39=0,"",INDEX(LIST!$C$3:$C$112,MATCH(LARGE(LIST!$I$3:$I$112,5),LIST!$I$3:$I$112,0))) | T39: =ROUND(INDEX(LIST!$E$3:$E$112,MATCH(LARGE(LIST!$I$3:$I$112,5),LIST!$I$3:$I$112,0)),1) | U39: =IF(T39=0,"",INDEX(LIST!$H$3:$H$112,MATCH(LARGE(LIST!$I$3:$I$112,5),LIST!$I$3:$I$112,0)))
P40: 6 | Q40: =IF(T40=0,"–",INDEX(LIST!$A$3:$A$112,MATCH(LARGE(LIST!$I$3:$I$112,6),LIST!$I$3:$I$112,0))) | R40: =IF(T40=0,"",INDEX(LIST!$C$3:$C$112,MATCH(LARGE(LIST!$I$3:$I$112,6),LIST!$I$3:$I$112,0))) | T40: =ROUND(INDEX(LIST!$E$3:$E$112,MATCH(LARGE(LIST!$I$3:$I$112,6),LIST!$I$3:$I$112,0)),1) | U40: =IF(T40=0,"",INDEX(LIST!$H$3:$H$112,MATCH(LARGE(LIST!$I$3:$I$112,6),LIST!$I$3:$I$112,0)))
P41: 7 | Q41: =IF(T41=0,"–",INDEX(LIST!$A$3:$A$112,MATCH(LARGE(LIST!$I$3:$I$112,7),LIST!$I$3:$I$112,0))) | R41: =IF(T41=0,"",INDEX(LIST!$C$3:$C$112,MATCH(LARGE(LIST!$I$3:$I$112,7),LIST!$I$3:$I$112,0))) | T41: =ROUND(INDEX(LIST!$E$3:$E$112,MATCH(LARGE(LIST!$I$3:$I$112,7),LIST!$I$3:$I$112,0)),1) | U41: =IF(T41=0,"",INDEX(LIST!$H$3:$H$112,MATCH(LARGE(LIST!$I$3:$I$112,7),LIST!$I$3:$I$112,0)))
P42: 8 | Q42: =IF(T42=0,"–",INDEX(LIST!$A$3:$A$112,MATCH(LARGE(LIST!$I$3:$I$112,8),LIST!$I$3:$I$112,0))) | R42: =IF(T42=0,"",INDEX(LIST!$C$3:$C$112,MATCH(LARGE(LIST!$I$3:$I$112,8),LIST!$I$3:$I$112,0))) | T42: =ROUND(INDEX(LIST!$E$3:$E$112,MATCH(LARGE(LIST!$I$3:$I$112,8),LIST!$I$3:$I$112,0)),1) | U42: =IF(T42=0,"",INDEX(LIST!$H$3:$H$112,MATCH(LARGE(LIST!$I$3:$I$112,8),LIST!$I$3:$I$112,0)))
P43: 9 | Q43: =IF(T43=0,"–",INDEX(LIST!$A$3:$A$112,MATCH(LARGE(LIST!$I$3:$I$112,9),LIST!$I$3:$I$112,0))) | R43: =IF(T43=0,"",INDEX(LIST!$C$3:$C$112,MATCH(LARGE(LIST!$I$3:$I$112,9),LIST!$I$3:$I$112,0))) | T43: =ROUND(INDEX(LIST!$E$3:$E$112,MATCH(LARGE(LIST!$I$3:$I$112,9),LIST!$I$3:$I$112,0)),1) | U43: =IF(T43=0,"",INDEX(LIST!$H$3:$H$112,MATCH(LARGE(LIST!$I$3:$I$112,9),LIST!$I$3:$I$112,0)))
P44: 10 | Q44: =IF(T44=0,"–",INDEX(LIST!$A$3:$A$112,MATCH(LARGE(LIST!$I$3:$I$112,10),LIST!$I$3:$I$112,0))) | R44: =IF(T44=0,"",INDEX(LIST!$C$3:$C$112,MATCH(LARGE(LIST!$I$3:$I$112,10),LIST!$I$3:$I$112,0))) | T44: =ROUND(INDEX(LIST!$E$3:$E$112,MATCH(LARGE(LIST!$I$3:$I$112,10),LIST!$I$3:$I$112,0)),1) | U44: =IF(T44=0,"",INDEX(LIST!$H$3:$H$112,MATCH(LARGE(LIST!$I$3:$I$112,10),LIST!$I$3:$I$112,0)))

Sheet Delay & Hujan
B2: PIT CONTROL | D2: Mine Ops Board / Delay & Hujan
B3: MINE OPS BOARD | D3: Delay & Hujan
D4: Idle = jam unit siap pakai tetapi tidak bekerja, per kategori timesheet
B5: BOARD
B6: =HYPERLINK("#Produksi!A1"," Produksi") | E6: Dari | F6: 46082 | H6: Sampai | I6: 46110 | K6: Shift | L6: Semua | N6: Class | O6: Semua
B7: =HYPERLINK("#Digger!A1"," Produktivitas Digger") | D7: =IF(Kalkulasi!$B$33=0,"⚠ Tanggal akhir harus sama atau setelah tanggal mulai","Klik sel kuning untuk memilih filter · "&Kalkulasi!$B$33&" hari dipilih")
B8: =HYPERLINK("#Availability!A1"," Availability Unit")
B9: =HYPERLINK("#'Delay & Hujan'!A1"," Delay & Hujan") | D9: TOTAL IDLE | G9: IDLE KARENA CUACA | J9: JAM HUJAN | M9: SLIPPERY | P9: CURAH HUJAN | S9: IDLE / HARI
B10: =HYPERLINK("#Fuel!A1"," Fuel") | D10: =Kalkulasi!$B$72 | G10: =Kalkulasi!$B$73 | J10: =Kalkulasi!$B$75 | M10: =Kalkulasi!$B$76 | P10: =Kalkulasi!$B$77 | S10: =IF(Kalkulasi!$B$33=0,0,Kalkulasi!$B$72/Kalkulasi!$B$33)
B11: =HYPERLINK("#'Tren PTY'!A1"," Tren PTY") | D11: ="Terbesar: "&Kalkulasi!$E$262 | G11: =TEXT(Kalkulasi!$B$74,"0%")&" dari idle (rain + slippery)" | J11: =TEXT(Kalkulasi!$B$214,"0")&" hari hujan" | M11: ="Jalan licin setelah hujan" | P11: ="Pengukuran pit" | S11: ="Rata-rata jam unit per hari"
B13: PER JAM | D13: Pareto idle | O13: 10 kategori terbesar · garis = kumulatif (%) | P13: Semua kategori idle
B14: =HYPERLINK("#'PTY per Jam'!A1"," PTY per Jam") | P14: Kategori | S14: Jam | T14: Porsi
B15: =HYPERLINK("#'Fleet & Delay'!A1"," Fleet & Delay") | P15: =Kalkulasi!E262 | S15: =Kalkulasi!F262 | T15: =Kalkulasi!H262
